File: Magnetic_Nanoparticle_Granulometry/AND100-810-ac4ft-5-80K.ac.dat.csv
[Header],,,,,,,,,,,,,,,,,,,,,,,,,,,
TITLE,MPMS AC Measurement,,,,,,,,,,,,,,,,,,,,,,,,,,
BYAPP,MPMS Measurement,1.1,Summary,,,,,,,,,,,,,,,,,,,,,,,,
FILEOPENTIME, 1715123684.744000 5/7/2024, 5:14:44 PM,,,,,,,,,,,,,,,,,,,,,,,,,
,,,,,,,,,,,,,,,,,,,,,,,,,,,
INFO, APPNAME, MPMS MultiVu Application, Revision 1.61,  Build 082,,,,,,,,,,,,,,,,,,,,,,,
,,,,,,,,,,,,,,,,,,,,,,,,,,,
INFO, NAME, AND100-810,,,,,,,,,,,,,,,,,,,,,,,,,
INFO, WEIGHT,149.41,,,,,,,,,,,,,,,,,,,,,,,,,
INFO, AREA,1,,,,,,,,,,,,,,,,,,,,,,,,,
INFO, LENGTH,1,,,,,,,,,,,,,,,,,,,,,,,,,
INFO, SHAPE,1,,,,,,,,,,,,,,,,,,,,,,,,,
INFO, COMMENT, ,,,,,,,,,,,,,,,,,,,,,,,,,
INFO, SEQUENCE FILE: AC Wakeup.seq,,,,,,,,,,,,,,,,,,,,,,,,,,
,,,,,,,,,,,,,,,,,,,,,,,,,,,
STARTUPAXIS,X,4,LINEAR,AUTO,0,0,,,,,,,,,,,,,,,,,,,,,
STARTUPAXIS,Y1,5,LINEAR,AUTO,0,0,,,,,,,,,,,,,,,,,,,,,
STARTUPAXIS,Y2,7,LINEAR,AUTO,0,0,,,,,,,,,,,,,,,,,,,,,
,,,,,,,,,,,,,,,,,,,,,,,,,,,
,,,,,,,,,,,,,,,,,,,,,,,,,,,
STARTUPGROUP,"m' and m""",,,,,,,,,,,,,,,,,,,,,,,,,,
FIELDGROUP,"m' and m""",1,2,3,4,14,15,5,6,7,8,13,26,27,28,,,,,,,,,,,,
FIELDGROUP,Amplitude and Phase,1,2,3,4,14,15,9,10,11,12,13,26,27,28,,,,,,,,,,,,
,,,,,,,,,,,,,,,,,,,,,,,,,,,
PLOT_APPEARANCE,ALL,HORZ_GRID_ON,VERT_GRID_ON,MARKERS_AND_LINES,,,,,,,,,,,,,,,,,,,,,,,
,,,,,,,,,,,,,,,,,,,,,,,,,,,
[Data],,,,,,,,,,,,,,,,,,,,,,,,,,,
Time,Comment,Field (Oe),Temperature (K),m' (emu),m' Scan Std Dev,"m"" (emu)","m"" Scan Std Dev",Amplitude (emu),Amplitude Scan Std Dev,Phase (deg),Phase Scan Std Dev,Regression Fit,Drive Amplitude (Oe),Wave Frequency (Hz),Steps per Cycle,Blocks to Average,Scans per Measurement,Clock Frequency,Amplifier Gain,AC Filter,Two Point Measurement,Scan Length,Settling Time (sec),Delta Temp (K),Rot Position (Oe),Error,% Clipped
1715124079,,0.00E+00,5.00E+00,3.12E-04,1.99E-07,7.98E-06,1.67E-08,3.13E-04,2.00E-07,1.46E+00,2.18E-03,1.00E+00,3.00E+00,1.00E+00,732,10,3,2,0,3,1,4.00E+00,1,1.67E-03,0.00E+00,0,0.00E+00
1715124288,,0.00E+00,5.00E+00,3.01E-04,3.83E-08,6.19E-06,8.51E-09,3.01E-04,3.85E-08,1.18E+00,1.48E-03,1.00E+00,3.00E+00,1.00E+01,1172,10,3,3,0,2,1,4.00E+00,1,1.16E-03,0.00E+00,0,0.00E+00
1715124448,,0.00E+00,5.00E+00,2.92E-04,2.46E-08,5.16E-06,8.31E-09,2.92E-04,2.47E-08,1.01E+00,1.58E-03,1.00E+00,3.00E+00,9.98E+01,1878,10,3,4,0,1,1,4.00E+00,1,1.54E-03,0.00E+00,0,0.00E+00
1715124624,,0.00E+00,5.00E+00,2.86E-04,9.04E-08,3.49E-06,1.05E-07,2.86E-04,9.09E-08,6.99E-01,2.10E-02,1.00E+00,3.00E+00,9.97E+02,188,10,3,4,0,0,1,4.00E+00,1,1.41E-03,0.00E+00,0,0.00E+00
1715125105,,0.00E+00,6.97E+00,3.31E-04,4.80E-07,1.58E-05,9.15E-08,3.31E-04,4.83E-07,2.74E+00,1.18E-02,1.00E+00,3.00E+00,1.00E+00,732,10,3,2,0,3,1,4.00E+00,1,8.28E-03,0.00E+00,0,0.00E+00
1715125306,,0.00E+00,6.97E+00,3.09E-04,1.53E-07,1.18E-05,3.02E-08,3.10E-04,1.54E-07,2.19E+00,4.54E-03,1.00E+00,3.00E+00,1.00E+01,1172,10,3,3,0,2,1,4.00E+00,1,3.72E-03,0.00E+00,0,0.00E+00
1715125474,,0.00E+00,6.97E+00,2.93E-04,4.69E-08,9.11E-06,3.58E-08,2.94E-04,4.71E-08,1.78E+00,6.93E-03,1.00E+00,3.00E+00,9.98E+01,1878,10,3,4,0,1,1,4.00E+00,1,8.57E-04,0.00E+00,0,0.00E+00
1715125661,,0.00E+00,6.98E+00,2.82E-04,3.77E-08,6.26E-06,8.72E-08,2.82E-04,3.75E-08,1.27E+00,1.78E-02,1.00E+00,3.00E+00,9.97E+02,188,10,3,4,0,0,1,4.00E+00,1,5.15E-03,0.00E+00,0,0.00E+00
1715126122,,0.00E+00,8.95E+00,3.73E-04,7.73E-07,2.93E-05,1.65E-07,3.74E-04,7.83E-07,4.49E+00,1.59E-02,1.00E+00,3.00E+00,1.00E+00,732,10,3,2,0,3,1,4.00E+00,1,5.49E-03,0.00E+00,0,0.00E+00
1715126314,,0.00E+00,8.95E+00,3.34E-04,1.39E-07,2.14E-05,2.05E-08,3.35E-04,1.40E-07,3.66E+00,2.01E-03,1.00E+00,3.00E+00,1.00E+01,1172,10,3,3,0,2,1,4.00E+00,1,1.50E-03,0.00E+00,0,0.00E+00
1715126471,,0.00E+00,8.95E+00,3.06E-04,2.83E-08,1.58E-05,2.97E-08,3.07E-04,2.96E-08,2.94E+00,5.30E-03,1.00E+00,3.00E+00,9.98E+01,1878,10,3,4,0,1,1,4.00E+00,1,1.25E-03,0.00E+00,0,0.00E+00
1715126618,,0.00E+00,8.95E+00,2.87E-04,4.66E-08,1.08E-05,2.87E-08,2.87E-04,4.69E-08,2.16E+00,5.64E-03,1.00E+00,3.00E+00,9.97E+02,188,10,3,4,0,0,1,4.00E+00,1,2.25E-03,0.00E+00,0,0.00E+00
1715127089,,0.00E+00,1.09E+01,4.48E-04,9.82E-07,5.10E-05,2.68E-07,4.51E-04,1.01E-06,6.49E+00,1.97E-02,1.00E+00,3.00E+00,1.00E+00,732,10,3,2,0,3,1,4.00E+00,1,2.19E-03,0.00E+00,0,0.00E+00
1715127279,,0.00E+00,1.09E+01,3.82E-04,1.38E-07,3.69E-05,3.71E-08,3.84E-04,1.41E-07,5.51E+00,3.59E-03,1.00E+00,3.00E+00,1.00E+01,1172,10,3,3,0,2,1,4.00E+00,1,1.42E-03,0.00E+00,0,0.00E+00
1715127442,,0.00E+00,1.09E+01,3.35E-04,4.07E-08,2.66E-05,3.22E-09,3.36E-04,4.06E-08,4.55E+00,7.53E-04,1.00E+00,3.00E+00,9.98E+01,1878,10,3,4,0,1,1,4.00E+00,1,1.26E-03,0.00E+00,0,0.00E+00
1715127599,,0.00E+00,1.09E+01,3.03E-04,6.31E-08,1.81E-05,4.99E-08,3.03E-04,6.36E-08,3.41E+00,9.30E-03,1.00E+00,3.00E+00,9.97E+02,188,10,3,4,0,0,1,4.00E+00,1,1.42E-03,0.00E+00,0,0.00E+00
1715128115,,0.00E+00,1.29E+01,5.61E-04,1.26E-06,8.27E-05,3.37E-07,5.67E-04,1.29E-06,8.39E+00,1.52E-02,1.00E+00,3.00E+00,1.00E+00,732,10,3,2,0,3,1,4.00E+00,1,9.79E-04,0.00E+00,0,0.00E+00
1715128307,,0.00E+00,1.29E+01,4.55E-04,1.32E-07,5.98E-05,4.77E-08,4.59E-04,1.37E-07,7.48E+00,3.77E-03,1.00E+00,3.00E+00,1.00E+01,1172,10,3,3,0,2,1,4.00E+00,1,1.47E-03,0.00E+00,0,0.00E+00
1715128465,,0.00E+00,1.29E+01,3.80E-04,9.01E-08,4.29E-05,4.55E-08,3.82E-04,8.97E-08,6.44E+00,6.93E-03,1.00E+00,3.00E+00,9.98E+01,1878,10,3,4,0,1,1,4.00E+00,1,1.95E-03,0.00E+00,0,0.00E+00
1715128621,,0.00E+00,1.29E+01,3.31E-04,7.87E-08,2.88E-05,6.25E-08,3.32E-04,7.41E-08,4.97E+00,1.17E-02,1.00E+00,3.00E+00,9.97E+02,188,10,3,4,0,0,1,4.00E+00,1,8.50E-04,0.00E+00,0,0.00E+00
1715129087,,0.00E+00,1.49E+01,7.26E-04,1.31E-06,1.27E-04,3.96E-07,7.37E-04,1.36E-06,9.94E+00,1.27E-02,1.00E+00,3.00E+00,1.00E+00,732,10,3,2,0,3,1,4.00E+00,1,5.05E-03,0.00E+00,0,0.00E+00
1715129293,,0.00E+00,1.49E+01,5.64E-04,1.32E-07,9.22E-05,4.66E-08,5.72E-04,1.38E-07,9.28E+00,2.65E-03,1.00E+00,3.00E+00,1.00E+01,1172,10,3,3,0,2,1,4.00E+00,1,1.90E-03,0.00E+00,0,0.00E+00
1715129455,,0.00E+00,1.49E+01,4.49E-04,5.11E-08,6.60E-05,6.46E-08,4.54E-04,5.81E-08,8.36E+00,7.37E-03,1.00E+00,3.00E+00,9.98E+01,1878,10,3,4,0,1,1,4.00E+00,1,3.16E-03,0.00E+00,0,0.00E+00
1715129648,,0.00E+00,1.49E+01,3.72E-04,2.24E-08,4.44E-05,4.13E-08,3.75E-04,2.40E-08,6.80E+00,6.18E-03,1.00E+00,3.00E+00,9.97E+02,188,10,3,4,0,0,1,4.00E+00,1,1.90E-03,0.00E+00,0,0.00E+00
1715130185,,0.00E+00,1.68E+01,9.50E-04,1.64E-06,1.85E-04,4.54E-07,9.67E-04,1.69E-06,1.10E+01,7.86E-03,1.00E+00,3.00E+00,1.00E+00,732,10,3,2,0,3,1,4.00E+00,1,8.01E-03,0.00E+00,0,0.00E+00
1715130397,,0.00E+00,1.68E+01,7.15E-04,1.32E-07,1.35E-04,2.03E-08,7.27E-04,1.33E-07,1.07E+01,4.47E-04,1.00E+00,3.00E+00,1.00E+01,1172,10,3,3,0,2,1,4.00E+00,1,1.60E-03,0.00E+00,0,0.00E+00
1715130558,,0.00E+00,1.68E+01,5.45E-04,6.41E-08,9.74E-05,1.67E-08,5.54E-04,6.11E-08,1.01E+01,2.65E-03,1.00E+00,3.00E+00,9.98E+01,1878,10,3,4,0,1,1,4.00E+00,1,4.00E-03,0.00E+00,0,0.00E+00
1715130720,,0.00E+00,1.68E+01,4.32E-04,5.22E-08,6.60E-05,5.23E-08,4.37E-04,5.62E-08,8.70E+00,6.30E-03,1.00E+00,3.00E+00,9.97E+02,188,10,3,4,0,0,1,4.00E+00,1,8.82E-03,0.00E+00,0,0.00E+00
1715131315,,0.00E+00,1.88E+01,1.24E-03,1.44E-06,2.55E-04,4.19E-07,1.26E-03,1.49E-06,1.17E+01,5.59E-03,1.00E+00,3.00E+00,1.00E+00,732,10,3,2,0,3,1,4.00E+00,1,8.86E-03,0.00E+00,0,0.00E+00
1715131522,,0.00E+00,1.88E+01,9.12E-04,1.18E-07,1.90E-04,4.87E-08,9.32E-04,1.25E-07,1.17E+01,1.69E-03,1.00E+00,3.00E+00,1.00E+01,1172,10,3,3,0,2,1,4.00E+00,1,4.92E-03,0.00E+00,0,0.00E+00
1715131700,,0.00E+00,1.88E+01,6.74E-04,1.19E-07,1.38E-04,3.96E-08,6.88E-04,1.24E-07,1.15E+01,1.28E-03,1.00E+00,3.00E+00,9.98E+01,1878,10,3,4,0,1,1,4.00E+00,1,1.97E-03,0.00E+00,0,0.00E+00
1715131896,,0.00E+00,1.88E+01,5.12E-04,6.16E-08,9.44E-05,4.81E-08,5.20E-04,5.69E-08,1.05E+01,5.89E-03,1.00E+00,3.00E+00,9.97E+02,188,10,3,4,0,0,1,4.00E+00,1,3.93E-03,0.00E+00,0,0.00E+00
1715132473,,0.00E+00,2.08E+01,1.59E-03,1.33E-06,3.35E-04,3.98E-07,1.63E-03,1.38E-06,1.19E+01,4.11E-03,1.00E+00,3.00E+00,1.00E+00,732,10,3,2,0,3,1,4.00E+00,1,4.72E-03,0.00E+00,0,0.00E+00
1715132673,,0.00E+00,2.08E+01,1.16E-03,1.13E-07,2.54E-04,3.56E-08,1.19E-03,1.17E-07,1.23E+01,9.08E-04,1.00E+00,3.00E+00,1.00E+01,1172,10,3,3,0,2,1,4.00E+00,1,2.36E-03,0.00E+00,0,0.00E+00
1715132843,,0.00E+00,2.08E+01,8.39E-04,1.12E-07,1.87E-04,5.00E-08,8.60E-04,1.20E-07,1.26E+01,1.64E-03,1.00E+00,3.00E+00,9.98E+01,1878,10,3,4,0,1,1,4.00E+00,1,5.90E-03,0.00E+00,0,0.00E+00
1715133006,,0.00E+00,2.08E+01,6.16E-04,1.29E-07,1.30E-04,1.08E-07,6.30E-04,1.48E-07,1.19E+01,7.28E-03,1.00E+00,3.00E+00,9.97E+02,188,10,3,4,0,0,1,4.00E+00,1,3.54E-03,0.00E+00,0,0.00E+00
1715133527,,0.00E+00,2.28E+01,2.00E-03,8.89E-07,4.15E-04,3.09E-07,2.05E-03,9.33E-07,1.17E+01,3.49E-03,1.00E+00,3.00E+00,1.00E+00,732,10,3,2,0,3,1,4.00E+00,1,6.25E-03,0.00E+00,0,0.00E+00
1715133726,,0.00E+00,2.28E+01,1.46E-03,1.25E-07,3.25E-04,2.91E-08,1.49E-03,1.28E-07,1.26E+01,3.86E-04,1.00E+00,3.00E+00,1.00E+01,1172,10,3,3,0,2,1,4.00E+00,1,2.78E-03,0.00E+00,0,0.00E+00
1715133894,,0.00E+00,2.28E+01,1.04E-03,1.68E-07,2.45E-04,3.42E-08,1.07E-03,1.70E-07,1.32E+01,1.10E-03,1.00E+00,3.00E+00,9.98E+01,1878,10,3,4,0,1,1,4.00E+00,1,2.77E-03,0.00E+00,0,0.00E+00
1715134038,,0.00E+00,2.28E+01,7.46E-04,1.83E-07,1.73E-04,1.14E-07,7.66E-04,2.04E-07,1.30E+01,5.33E-03,1.00E+00,3.00E+00,9.97E+02,188,10,3,4,0,0,1,4.00E+00,1,1.32E-02,0.00E+00,0,0.00E+00
1715134485,,0.00E+00,2.47E+01,2.45E-03,7.63E-07,4.81E-04,1.65E-07,2.50E-03,7.81E-07,1.11E+01,3.45E-04,1.00E+00,3.00E+00,1.00E+00,732,10,3,2,0,3,1,4.00E+00,1,2.42E-03,0.00E+00,0,0.00E+00
1715134678,,0.00E+00,2.47E+01,1.80E-03,2.79E-07,3.96E-04,5.91E-08,1.84E-03,2.85E-07,1.24E+01,3.56E-04,1.00E+00,3.00E+00,1.00E+01,1172,10,3,3,0,2,1,4.00E+00,1,2.41E-03,0.00E+00,0,0.00E+00
1715134855,,0.00E+00,2.47E+01,1.28E-03,1.33E-07,3.07E-04,4.57E-08,1.32E-03,1.40E-07,1.35E+01,7.79E-04,1.00E+00,3.00E+00,9.98E+01,1878,10,3,4,0,1,1,4.00E+00,1,1.21E-02,0.00E+00,0,0.00E+00
1715135053,,0.00E+00,2.47E+01,9.03E-04,4.81E-08,2.22E-04,1.21E-07,9.30E-04,7.52E-08,1.38E+01,6.54E-03,1.00E+00,3.00E+00,9.97E+02,188,10,3,4,0,0,1,4.00E+00,1,1.28E-02,0.00E+00,0,0.00E+00
1715135602,,0.00E+00,2.67E+01,2.90E-03,4.42E-07,5.22E-04,1.33E-07,2.95E-03,4.58E-07,1.02E+01,1.12E-03,1.00E+00,3.00E+00,1.00E+00,732,10,3,2,0,3,1,4.00E+00,1,5.52E-03,0.00E+00,0,0.00E+00
1715135790,,0.00E+00,2.67E+01,2.16E-03,4.24E-07,4.59E-04,1.01E-07,2.21E-03,4.35E-07,1.20E+01,3.50E-04,1.00E+00,3.00E+00,1.00E+01,1172,10,3,3,0,2,1,4.00E+00,1,1.29E-02,0.00E+00,0,0.00E+00
1715135950,,0.00E+00,2.67E+01,1.55E-03,3.99E-07,3.71E-04,1.25E-07,1.59E-03,4.17E-07,1.35E+01,1.05E-03,1.00E+00,3.00E+00,9.98E+01,1878,10,3,4,0,1,1,4.00E+00,1,3.68E-03,0.00E+00,0,0.00E+00
1715136134,,0.00E+00,2.67E+01,1.08E-03,1.35E-07,2.75E-04,6.44E-08,1.12E-03,1.16E-07,1.42E+01,4.87E-03,1.00E+00,3.00E+00,9.97E+02,188,10,3,4,0,0,1,4.00E+00,1,4.61E-03,0.00E+00,0,0.00E+00
1715136681,,0.00E+00,2.87E+01,3.31E-03,5.29E-07,5.28E-04,1.14E-07,3.36E-03,5.40E-07,9.04E+00,6.48E-04,1.00E+00,3.00E+00,1.00E+00,732,10,3,2,0,3,1,4.00E+00,1,7.29E-03,0.00E+00,0,0.00E+00
1715136877,,0.00E+00,2.87E+01,2.54E-03,2.80E-07,5.02E-04,7.58E-08,2.59E-03,2.90E-07,1.12E+01,4.84E-04,1.00E+00,3.00E+00,1.00E+01,1172,10,3,3,0,2,1,4.00E+00,1,7.30E-03,0.00E+00,0,0.00E+00
1715137055,,0.00E+00,2.87E+01,1.84E-03,3.49E-07,4.29E-04,9.00E-08,1.89E-03,3.60E-07,1.31E+01,3.43E-04,1.00E+00,3.00E+00,9.98E+01,1878,10,3,4,0,1,1,4.00E+00,1,7.29E-03,0.00E+00,0,0.00E+00
1715137210,,0.00E+00,2.87E+01,1.29E-03,2.28E-07,3.31E-04,1.03E-07,1.33E-03,2.44E-07,1.44E+01,2.43E-03,1.00E+00,3.00E+00,9.97E+02,188,10,3,4,0,0,1,4.00E+00,1,2.08E-03,0.00E+00,0,0.00E+00
1715137712,,0.00E+00,3.07E+01,3.66E-03,4.29E-07,5.01E-04,4.64E-08,3.70E-03,4.31E-07,7.78E+00,3.05E-04,1.00E+00,3.00E+00,1.00E+00,732,10,3,2,0,3,1,4.00E+00,1,1.76E-02,0.00E+00,0,0.00E+00
1715137900,,0.00E+00,3.07E+01,2.89E-03,4.73E-07,5.19E-04,8.18E-08,2.94E-03,4.80E-07,1.02E+01,5.23E-04,1.00E+00,3.00E+00,1.00E+01,1172,10,3,3,0,2,1,4.00E+00,1,3.51E-03,0.00E+00,0,0.00E+00
1715138080,,0.00E+00,3.07E+01,2.14E-03,5.18E-08,4.75E-04,3.79E-08,2.19E-03,5.30E-08,1.25E+01,9.49E-04,1.00E+00,3.00E+00,9.98E+01,1878,10,3,4,0,1,1,4.00E+00,1,8.20E-03,0.00E+00,0,0.00E+00
1715138263,,0.00E+00,3.07E+01,1.51E-03,1.45E-07,3.84E-04,4.49E-08,1.56E-03,1.40E-07,1.42E+01,2.18E-03,1.00E+00,3.00E+00,9.97E+02,188,10,3,4,0,0,1,4.00E+00,1,1.17E-03,0.00E+00,0,0.00E+00
1715138737,,0.00E+00,3.26E+01,3.93E-03,3.46E-07,4.50E-04,2.14E-08,3.95E-03,3.44E-07,6.53E+00,5.46E-04,1.00E+00,3.00E+00,1.00E+00,732,10,3,2,0,3,1,4.00E+00,1,6.54E-03,0.00E+00,0,0.00E+00
1715138941,,0.00E+00,3.26E+01,3.20E-03,5.09E-07,5.08E-04,6.30E-08,3.24E-03,5.12E-07,9.01E+00,6.03E-04,1.00E+00,3.00E+00,1.00E+01,1172,10,3,3,0,2,1,4.00E+00,1,6.53E-03,0.00E+00,0,0.00E+00
1715139113,,0.00E+00,3.26E+01,2.44E-03,4.61E-07,5.04E-04,1.05E-07,2.49E-03,4.73E-07,1.17E+01,3.84E-04,1.00E+00,3.00E+00,9.98E+01,1878,10,3,4,0,1,1,4.00E+00,1,1.70E-02,0.00E+00,0,0.00E+00
1715139287,,0.00E+00,3.26E+01,1.75E-03,3.06E-07,4.31E-04,1.57E-07,1.80E-03,2.91E-07,1.39E+01,5.83E-03,1.00E+00,3.00E+00,9.97E+02,188,10,3,4,0,0,1,4.00E+00,1,6.54E-03,0.00E+00,0,0.00E+00
1715139765,,0.00E+00,3.46E+01,4.10E-03,3.37E-07,3.87E-04,3.54E-08,4.12E-03,3.39E-07,5.38E+00,1.04E-04,1.00E+00,3.00E+00,1.00E+00,732,10,3,2,0,3,1,4.00E+00,1,8.69E-03,0.00E+00,0,0.00E+00
1715139968,,0.00E+00,3.46E+01,3.46E-03,2.43E-07,4.74E-04,3.64E-08,3.49E-03,2.45E-07,7.80E+00,1.65E-04,1.00E+00,3.00E+00,1.00E+01,1172,10,3,3,0,2,1,4.00E+00,1,4.35E-03,0.00E+00,0,0.00E+00
1715140139,,0.00E+00,3.46E+01,2.71E-03,3.58E-07,5.10E-04,3.77E-08,2.76E-03,3.54E-07,1.07E+01,1.30E-03,1.00E+00,3.00E+00,9.98E+01,1878,10,3,4,0,1,1,4.00E+00,1,1.30E-02,0.00E+00,0,0.00E+00
1715140320,,0.00E+00,3.46E+01,1.99E-03,1.92E-07,4.67E-04,5.30E-08,2.04E-03,1.85E-07,1.32E+01,2.07E-03,1.00E+00,3.00E+00,9.97E+02,188,10,3,4,0,0,1,4.00E+00,1,1.01E-02,0.00E+00,0,0.00E+00
1715140805,,0.00E+00,3.66E+01,4.20E-03,3.58E-07,3.21E-04,3.23E-08,4.21E-03,3.59E-07,4.37E+00,1.66E-04,1.00E+00,3.00E+00,1.00E+00,732,10,3,2,0,3,1,4.00E+00,1,1.60E-02,0.00E+00,0,0.00E+00
1715141005,,0.00E+00,3.66E+01,3.65E-03,4.81E-07,4.24E-04,6.59E-08,3.67E-03,4.85E-07,6.63E+00,4.21E-04,1.00E+00,3.00E+00,1.00E+01,1172,10,3,3,0,2,1,4.00E+00,1,1.60E-02,0.00E+00,0,0.00E+00
1715141183,,0.00E+00,3.66E+01,2.95E-03,4.79E-07,4.96E-04,1.10E-07,2.99E-03,4.90E-07,9.54E+00,6.55E-04,1.00E+00,3.00E+00,9.98E+01,1878,10,3,4,0,1,1,4.00E+00,1,2.56E-02,0.00E+00,0,0.00E+00
1715141350,,0.00E+00,3.66E+01,2.22E-03,4.03E-07,4.89E-04,9.41E-08,2.28E-03,4.02E-07,1.24E+01,2.42E-03,1.00E+00,3.00E+00,9.97E+02,188,10,3,4,0,0,1,4.00E+00,1,1.60E-03,0.00E+00,0,0.00E+00
1715141822,,0.00E+00,3.86E+01,4.23E-03,2.24E-07,2.60E-04,3.75E-08,4.24E-03,2.26E-07,3.51E+00,3.47E-04,1.00E+00,3.00E+00,1.00E+00,732,10,3,2,0,3,1,4.00E+00,1,1.05E-02,0.00E+00,0,0.00E+00
1715142022,,0.00E+00,3.86E+01,3.77E-03,4.67E-07,3.67E-04,6.53E-08,3.79E-03,4.69E-07,5.55E+00,7.27E-04,1.00E+00,3.00E+00,1.00E+01,1172,10,3,3,0,2,1,4.00E+00,1,2.80E-02,0.00E+00,0,0.00E+00
1715142191,,0.00E+00,3.86E+01,3.15E-03,4.28E-07,4.65E-04,4.77E-08,3.18E-03,4.25E-07,8.39E+00,1.18E-03,1.00E+00,3.00E+00,9.98E+01,1878,10,3,4,0,1,1,4.00E+00,1,5.25E-03,0.00E+00,0,0.00E+00
1715142365,,0.00E+00,3.86E+01,2.44E-03,5.23E-07,4.94E-04,2.39E-07,2.49E-03,5.52E-07,1.14E+01,3.67E-03,1.00E+00,3.00E+00,9.97E+02,188,10,3,4,0,0,1,4.00E+00,1,3.50E-03,0.00E+00,0,0.00E+00
1715142834,,0.00E+00,4.05E+01,4.21E-03,2.49E-07,2.05E-04,4.18E-08,4.22E-03,2.47E-07,2.79E+00,7.10E-04,1.00E+00,3.00E+00,1.00E+00,732,10,3,2,0,3,1,4.00E+00,1,1.72E-02,0.00E+00,0,0.00E+00
1715143028,,0.00E+00,4.05E+01,3.84E-03,5.58E-07,3.08E-04,4.20E-08,3.85E-03,5.58E-07,4.59E+00,6.88E-04,1.00E+00,3.00E+00,1.00E+01,1172,10,3,3,0,2,1,4.00E+00,1,3.83E-03,0.00E+00,0,0.00E+00
1715143193,,0.00E+00,4.05E+01,3.30E-03,3.07E-07,4.21E-04,3.82E-08,3.32E-03,3.05E-07,7.28E+00,9.25E-04,1.00E+00,3.00E+00,9.98E+01,1878,10,3,4,0,1,1,4.00E+00,1,5.74E-03,0.00E+00,0,0.00E+00
1715143357,,0.00E+00,4.05E+01,2.63E-03,5.26E-07,4.83E-04,6.21E-08,2.68E-03,5.28E-07,1.04E+01,7.67E-04,1.00E+00,3.00E+00,9.97E+02,188,10,3,4,0,0,1,4.00E+00,1,3.25E-02,0.00E+00,0,0.00E+00
1715143818,,0.00E+00,4.25E+01,4.16E-03,2.26E-07,1.59E-04,3.35E-08,4.16E-03,2.28E-07,2.19E+00,3.42E-04,1.00E+00,3.00E+00,1.00E+00,732,10,3,2,0,3,1,4.00E+00,1,1.25E-02,0.00E+00,0,0.00E+00
1715144020,,0.00E+00,4.25E+01,3.86E-03,6.98E-07,2.53E-04,3.31E-08,3.87E-03,6.98E-07,3.75E+00,2.83E-04,1.00E+00,3.00E+00,1.00E+01,1172,10,3,3,0,2,1,4.00E+00,1,1.66E-02,0.00E+00,0,0.00E+00
1715144199,,0.00E+00,4.25E+01,3.40E-03,2.26E-07,3.72E-04,3.37E-08,3.42E-03,2.22E-07,6.24E+00,9.23E-04,1.00E+00,3.00E+00,9.98E+01,1878,10,3,4,0,1,1,4.00E+00,1,1.66E-02,0.00E+00,0,0.00E+00
1715144371,,0.00E+00,4.25E+01,2.80E-03,2.75E-07,4.59E-04,1.12E-07,2.84E-03,2.88E-07,9.33E+00,1.52E-03,1.00E+00,3.00E+00,9.97E+02,188,10,3,4,0,0,1,4.00E+00,1,2.08E-02,0.00E+00,0,0.00E+00
1715144847,,0.00E+00,4.45E+01,4.07E-03,1.47E-07,1.21E-04,2.47E-08,4.07E-03,1.46E-07,1.71E+00,4.05E-04,1.00E+00,3.00E+00,1.00E+00,732,10,3,2,0,3,1,4.00E+00,1,2.03E-02,0.00E+00,0,0.00E+00
1715145052,,0.00E+00,4.45E+01,3.84E-03,4.65E-07,2.04E-04,2.45E-08,3.85E-03,4.64E-07,3.04E+00,5.57E-04,1.00E+00,3.00E+00,1.00E+01,1172,10,3,3,0,2,1,4.00E+00,1,1.13E-02,0.00E+00,0,0.00E+00
1715145230,,0.00E+00,4.45E+01,3.46E-03,4.48E-07,3.20E-04,5.82E-08,3.47E-03,4.41E-07,5.29E+00,1.58E-03,1.00E+00,3.00E+00,9.98E+01,1878,10,3,4,0,1,1,4.00E+00,1,1.58E-02,0.00E+00,0,0.00E+00
1715145387,,0.00E+00,4.45E+01,2.93E-03,4.66E-07,4.25E-04,4.99E-08,2.96E-03,4.63E-07,8.26E+00,1.48E-03,1.00E+00,3.00E+00,9.97E+02,188,10,3,4,0,0,1,4.00E+00,1,4.51E-03,0.00E+00,0,0.00E+00
1715145851,,0.00E+00,4.64E+01,3.97E-03,1.34E-07,9.12E-05,2.41E-08,3.97E-03,1.34E-07,1.32E+00,3.06E-04,1.00E+00,3.00E+00,1.00E+00,732,10,3,2,0,3,1,4.00E+00,1,1.46E-02,0.00E+00,0,0.00E+00
1715146051,,0.00E+00,4.64E+01,3.79E-03,3.60E-07,1.62E-04,8.22E-08,3.80E-03,3.58E-07,2.44E+00,1.39E-03,1.00E+00,3.00E+00,1.00E+01,1172,10,3,3,0,2,1,4.00E+00,1,9.73E-03,0.00E+00,0,0.00E+00
1715146232,,0.00E+00,4.64E+01,3.48E-03,4.37E-07,2.71E-04,2.53E-08,3.49E-03,4.35E-07,4.45E+00,8.75E-04,1.00E+00,3.00E+00,9.98E+01,1878,10,3,4,0,1,1,4.00E+00,1,4.86E-03,0.00E+00,0,0.00E+00
1715146391,,0.00E+00,4.64E+01,3.02E-03,6.05E-07,3.84E-04,8.82E-08,3.05E-03,6.08E-07,7.24E+00,1.23E-03,1.00E+00,3.00E+00,9.97E+02,188,10,3,4,0,0,1,4.00E+00,1,4.87E-03,0.00E+00,0,0.00E+00
1715146901,,0.00E+00,4.84E+01,3.86E-03,2.54E-07,6.78E-05,5.96E-08,3.86E-03,2.54E-07,1.01E+00,8.75E-04,1.00E+00,3.00E+00,1.00E+00,732,10,3,2,0,3,1,4.00E+00,1,7.86E-03,0.00E+00,0,0.00E+00
1715147087,,0.00E+00,4.84E+01,3.73E-03,4.12E-07,1.26E-04,5.41E-08,3.73E-03,4.10E-07,1.94E+00,1.04E-03,1.00E+00,3.00E+00,1.00E+01,1172,10,3,3,0,2,1,4.00E+00,1,1.05E-02,0.00E+00,0,0.00E+00
1715147268,,0.00E+00,4.84E+01,3.48E-03,7.58E-07,2.26E-04,9.68E-08,3.49E-03,7.58E-07,3.71E+00,1.65E-03,1.00E+00,3.00E+00,9.98E+01,1878,10,3,4,0,1,1,4.00E+00,1,2.10E-02,0.00E+00,0,0.00E+00
1715147409,,0.00E+00,4.84E+01,3.09E-03,7.84E-07,3.41E-04,1.91E-07,3.11E-03,7.65E-07,6.29E+00,4.75E-03,1.00E+00,3.00E+00,9.97E+02,188,10,3,4,0,0,1,4.00E+00,1,7.86E-03,0.00E+00,0,0.00E+00
1715147889,,0.00E+00,5.04E+01,3.75E-03,1.80E-07,4.98E-05,6.72E-08,3.75E-03,1.80E-07,7.62E-01,1.03E-03,1.00E+00,3.00E+00,1.00E+00,732,10,3,2,0,3,1,4.00E+00,1,8.44E-03,0.00E+00,0,0.00E+00
1715148072,,0.00E+00,5.04E+01,3.64E-03,6.06E-07,9.73E-05,4.84E-08,3.65E-03,6.05E-07,1.53E+00,8.93E-04,1.00E+00,3.00E+00,1.00E+01,1172,10,3,3,0,2,1,4.00E+00,1,5.63E-03,0.00E+00,0,0.00E+00
1715148252,,0.00E+00,5.04E+01,3.45E-03,2.92E-07,1.85E-04,1.57E-07,3.45E-03,2.83E-07,3.08E+00,2.85E-03,1.00E+00,3.00E+00,9.98E+01,1878,10,3,4,0,1,1,4.00E+00,1,1.69E-02,0.00E+00,0,0.00E+00
1715148409,,0.00E+00,5.04E+01,3.13E-03,7.55E-07,2.97E-04,1.95E-07,3.14E-03,7.36E-07,5.42E+00,4.71E-03,1.00E+00,3.00E+00,9.97E+02,188,10,3,4,0,0,1,4.00E+00,1,1.12E-02,0.00E+00,0,0.00E+00
1715148876,,0.00E+00,5.24E+01,3.63E-03,2.93E-07,3.61E-05,3.77E-08,3.63E-03,2.93E-07,5.71E-01,5.56E-04,1.00E+00,3.00E+00,1.00E+00,732,10,3,2,0,3,1,4.00E+00,1,1.69E-02,0.00E+00,0,0.00E+00
1715149074,,0.00E+00,5.24E+01,3.55E-03,2.29E-07,7.39E-05,8.65E-08,3.55E-03,2.27E-07,1.19E+00,1.47E-03,1.00E+00,3.00E+00,1.00E+01,1172,10,3,3,0,2,1,4.00E+00,1,2.41E-02,0.00E+00,0,0.00E+00
1715149242,,0.00E+00,5.24E+01,3.40E-03,5.05E-07,1.50E-04,1.16E-07,3.40E-03,5.00E-07,2.53E+00,2.26E-03,1.00E+00,3.00E+00,9.98E+01,1878,10,3,4,0,1,1,4.00E+00,1,1.69E-02,0.00E+00,0,0.00E+00
1715149393,,0.00E+00,5.24E+01,3.14E-03,5.85E-07,2.54E-04,1.78E-07,3.15E-03,5.78E-07,4.63E+00,3.64E-03,1.00E+00,3.00E+00,9.97E+02,188,10,3,4,0,0,1,4.00E+00,1,4.81E-03,0.00E+00,0,0.00E+00
1715149893,,0.00E+00,5.43E+01,3.51E-03,1.97E-07,2.61E-05,4.32E-08,3.51E-03,1.97E-07,4.26E-01,7.24E-04,1.00E+00,3.00E+00,1.00E+00,732,10,3,2,0,3,1,4.00E+00,1,1.93E-02,0.00E+00,0,0.00E+00
1715150063,,0.00E+00,5.43E+01,3.46E-03,3.71E-07,5.56E-05,9.92E-08,3.46E-03,3.69E-07,9.21E-01,1.74E-03,1.00E+00,3.00E+00,1.00E+01,1172,10,3,3,0,2,1,4.00E+00,1,1.29E-02,0.00E+00,0,0.00E+00
1715150241,,0.00E+00,5.43E+01,3.34E-03,4.07E-07,1.20E-04,1.55E-07,3.34E-03,4.01E-07,2.06E+00,2.91E-03,1.00E+00,3.00E+00,9.98E+01,1878,10,3,4,0,1,1,4.00E+00,1,2.19E-02,0.00E+00,0,0.00E+00
1715150406,,0.00E+00,5.43E+01,3.13E-03,5.35E-07,2.15E-04,1.30E-07,3.14E-03,5.26E-07,3.92E+00,2.91E-03,1.00E+00,3.00E+00,9.97E+02,188,10,3,4,0,0,1,4.00E+00,1,9.01E-03,0.00E+00,0,0.00E+00
1715150895,,0.00E+00,5.63E+01,3.40E-03,2.51E-07,1.87E-05,4.11E-08,3.40E-03,2.50E-07,3.14E-01,7.03E-04,1.00E+00,3.00E+00,1.00E+00,732,10,3,2,0,3,1,4.00E+00,1,9.61E-03,0.00E+00,0,0.00E+00
1715151075,,0.00E+00,5.63E+01,3.36E-03,1.26E-07,4.14E-05,1.36E-07,3.36E-03,1.24E-07,7.05E-01,2.34E-03,1.00E+00,3.00E+00,1.00E+01,1172,10,3,3,0,2,1,4.00E+00,1,1.65E-02,0.00E+00,0,0.00E+00
1715151251,,0.00E+00,5.63E+01,3.27E-03,2.90E-07,9.54E-05,1.19E-07,3.27E-03,2.87E-07,1.67E+00,2.19E-03,1.00E+00,3.00E+00,9.98E+01,1878,10,3,4,0,1,1,4.00E+00,1,6.87E-03,0.00E+00,0,0.00E+00
1715151410,,0.00E+00,5.63E+01,3.11E-03,6.25E-07,1.79E-04,1.37E-07,3.11E-03,6.21E-07,3.29E+00,2.88E-03,1.00E+00,3.00E+00,9.97E+02,188,10,3,4,0,0,1,4.00E+00,1,6.86E-03,0.00E+00,0,0.00E+00
1715151899,,0.00E+00,5.83E+01,3.29E-03,7.44E-07,1.32E-05,1.58E-08,3.29E-03,7.44E-07,2.29E-01,3.23E-04,1.00E+00,3.00E+00,1.00E+00,732,10,3,2,0,3,1,4.00E+00,1,1.75E-02,0.00E+00,0,0.00E+00
1715152073,,0.00E+00,5.83E+01,3.26E-03,3.60E-07,3.05E-05,5.18E-08,3.26E-03,3.59E-07,5.35E-01,9.68E-04,1.00E+00,3.00E+00,1.00E+01,1172,10,3,3,0,2,1,4.00E+00,1,1.31E-02,0.00E+00,0,0.00E+00
1715152243,,0.00E+00,5.83E+01,3.19E-03,4.30E-07,7.50E-05,6.70E-08,3.19E-03,4.30E-07,1.35E+00,1.21E-03,1.00E+00,3.00E+00,9.98E+01,1878,10,3,4,0,1,1,4.00E+00,1,1.90E-02,0.00E+00,0,0.00E+00
1715152367,,0.00E+00,5.83E+01,3.07E-03,3.36E-07,1.47E-04,1.08E-07,3.07E-03,3.33E-07,2.74E+00,2.15E-03,1.00E+00,3.00E+00,9.97E+02,188,10,3,4,0,0,1,4.00E+00,1,1.46E-02,0.00E+00,0,0.00E+00
1715152885,,0.00E+00,6.03E+01,3.19E-03,2.97E-07,9.28E-06,3.03E-08,3.19E-03,2.97E-07,1.67E-01,5.60E-04,1.00E+00,3.00E+00,1.00E+00,732,10,3,2,0,3,1,4.00E+00,1,1.86E-02,0.00E+00,0,0.00E+00
1715153069,,0.00E+00,6.03E+01,3.17E-03,1.64E-07,2.22E-05,3.67E-08,3.17E-03,1.63E-07,4.01E-01,6.75E-04,1.00E+00,3.00E+00,1.00E+01,1172,10,3,3,0,2,1,4.00E+00,1,1.86E-02,0.00E+00,0,0.00E+00
1715153240,,0.00E+00,6.03E+01,3.11E-03,2.40E-07,5.85E-05,1.62E-07,3.12E-03,2.38E-07,1.08E+00,3.03E-03,1.00E+00,3.00E+00,9.98E+01,1878,10,3,4,0,1,1,4.00E+00,1,2.17E-02,0.00E+00,0,0.00E+00
1715153367,,0.00E+00,6.03E+01,3.02E-03,2.10E-07,1.19E-04,1.37E-08,3.03E-03,2.10E-07,2.26E+00,3.11E-04,1.00E+00,3.00E+00,9.97E+02,188,10,3,4,0,0,1,4.00E+00,1,1.08E-02,0.00E+00,0,0.00E+00
1715153860,,0.00E+00,6.22E+01,3.09E-03,4.04E-08,6.49E-06,9.20E-09,3.09E-03,4.04E-08,1.20E-01,1.72E-04,1.00E+00,3.00E+00,1.00E+00,732,10,3,2,0,3,1,4.00E+00,1,4.76E-02,0.00E+00,0,0.00E+00
1715154047,,0.00E+00,6.22E+01,3.08E-03,7.00E-08,1.59E-05,2.21E-08,3.08E-03,7.01E-08,2.96E-01,4.09E-04,1.00E+00,3.00E+00,1.00E+01,1172,10,3,3,0,2,1,4.00E+00,1,8.20E-03,0.00E+00,0,0.00E+00
1715154226,,0.00E+00,6.22E+01,3.04E-03,2.65E-07,4.54E-05,4.35E-08,3.04E-03,2.64E-07,8.58E-01,8.87E-04,1.00E+00,3.00E+00,9.98E+01,1878,10,3,4,0,1,1,4.00E+00,1,1.48E-02,0.00E+00,0,0.00E+00
1715154388,,0.00E+00,6.22E+01,2.97E-03,4.65E-07,9.52E-05,8.06E-08,2.97E-03,4.63E-07,1.84E+00,1.73E-03,1.00E+00,3.00E+00,9.97E+02,188,10,3,4,0,0,1,4.00E+00,1,6.56E-03,0.00E+00,0,0.00E+00
1715154867,,0.00E+00,6.42E+01,3.00E-03,4.34E-07,4.44E-06,3.72E-08,3.00E-03,4.34E-07,8.48E-02,7.22E-04,1.00E+00,3.00E+00,1.00E+00,732,10,3,2,0,3,1,4.00E+00,1,8.67E-03,0.00E+00,0,0.00E+00
1715155035,,0.00E+00,6.42E+01,2.99E-03,2.43E-07,1.13E-05,1.55E-08,2.99E-03,2.43E-07,2.16E-01,2.80E-04,1.00E+00,3.00E+00,1.00E+01,1172,10,3,3,0,2,1,4.00E+00,1,1.21E-02,0.00E+00,0,0.00E+00
1715155208,,0.00E+00,6.42E+01,2.96E-03,8.98E-08,3.50E-05,1.03E-07,2.96E-03,9.04E-08,6.79E-01,1.99E-03,1.00E+00,3.00E+00,9.98E+01,1878,10,3,4,0,1,1,4.00E+00,1,1.04E-02,0.00E+00,0,0.00E+00
1715155357,,0.00E+00,6.42E+01,2.91E-03,1.18E-07,7.52E-05,1.47E-07,2.91E-03,1.14E-07,1.48E+00,2.96E-03,1.00E+00,3.00E+00,9.97E+02,188,10,3,4,0,0,1,4.00E+00,1,3.82E-02,0.00E+00,0,0.00E+00
1715155850,,0.00E+00,6.62E+01,2.91E-03,2.65E-07,3.05E-06,6.42E-08,2.91E-03,2.65E-07,6.00E-02,1.27E-03,1.00E+00,3.00E+00,1.00E+00,732,10,3,2,0,3,1,4.00E+00,1,5.49E-03,0.00E+00,0,0.00E+00
1715156027,,0.00E+00,6.62E+01,2.90E-03,1.85E-07,7.85E-06,1.66E-08,2.90E-03,1.85E-07,1.55E-01,3.32E-04,1.00E+00,3.00E+00,1.00E+01,1172,10,3,3,0,2,1,4.00E+00,1,3.11E-02,0.00E+00,0,0.00E+00
1715156198,,0.00E+00,6.62E+01,2.88E-03,1.15E-07,2.69E-05,7.13E-08,2.88E-03,1.14E-07,5.36E-01,1.44E-03,1.00E+00,3.00E+00,9.98E+01,1878,10,3,4,0,1,1,4.00E+00,1,2.01E-02,0.00E+00,0,0.00E+00
1715156345,,0.00E+00,6.62E+01,2.85E-03,2.11E-07,5.85E-05,6.96E-08,2.85E-03,2.10E-07,1.18E+00,1.45E-03,1.00E+00,3.00E+00,9.97E+02,188,10,3,4,0,0,1,4.00E+00,1,5.49E-03,0.00E+00,0,0.00E+00
1715156842,,0.00E+00,6.82E+01,2.83E-03,3.69E-07,2.03E-06,2.74E-08,2.83E-03,3.69E-07,4.12E-02,5.57E-04,1.00E+00,3.00E+00,1.00E+00,732,10,3,2,0,3,1,4.00E+00,1,2.51E-02,0.00E+00,0,0.00E+00
1715157016,,0.00E+00,6.82E+01,2.82E-03,2.89E-07,5.30E-06,2.40E-08,2.82E-03,2.89E-07,1.08E-01,4.81E-04,1.00E+00,3.00E+00,1.00E+01,1172,10,3,3,0,2,1,4.00E+00,1,1.54E-02,0.00E+00,0,0.00E+00
1715157171,,0.00E+00,6.82E+01,2.80E-03,8.93E-08,2.06E-05,3.76E-08,2.80E-03,8.94E-08,4.20E-01,7.62E-04,1.00E+00,3.00E+00,9.98E+01,1878,10,3,4,0,1,1,4.00E+00,1,1.35E-02,0.00E+00,0,0.00E+00
1715157312,,0.00E+00,6.82E+01,2.78E-03,1.84E-07,4.51E-05,1.24E-07,2.78E-03,1.82E-07,9.27E-01,2.60E-03,1.00E+00,3.00E+00,9.97E+02,188,10,3,4,0,0,1,4.00E+00,1,1.74E-02,0.00E+00,0,0.00E+00
1715157812,,0.00E+00,7.01E+01,2.75E-03,3.90E-07,1.33E-06,3.10E-08,2.75E-03,3.90E-07,2.77E-02,6.45E-04,1.00E+00,3.00E+00,1.00E+00,732,10,3,2,0,3,1,4.00E+00,1,3.05E-02,0.00E+00,0,0.00E+00
1715157984,,0.00E+00,7.01E+01,2.74E-03,4.82E-08,3.46E-06,2.51E-08,2.74E-03,4.81E-08,7.23E-02,5.24E-04,1.00E+00,3.00E+00,1.00E+01,1172,10,3,3,0,2,1,4.00E+00,1,8.13E-03,0.00E+00,0,0.00E+00
1715158138,,0.00E+00,7.01E+01,2.73E-03,5.50E-08,1.58E-05,3.50E-08,2.73E-03,5.51E-08,3.31E-01,7.29E-04,1.00E+00,3.00E+00,9.98E+01,1878,10,3,4,0,1,1,4.00E+00,1,1.01E-02,0.00E+00,0,0.00E+00
1715158287,,0.00E+00,7.01E+01,2.72E-03,1.80E-07,3.38E-05,1.02E-07,2.72E-03,1.81E-07,7.12E-01,2.11E-03,1.00E+00,3.00E+00,9.97E+02,188,10,3,4,0,0,1,4.00E+00,1,2.01E-03,0.00E+00,0,0.00E+00
1715158747,,0.00E+00,7.21E+01,2.67E-03,1.69E-07,8.66E-07,1.79E-08,2.67E-03,1.69E-07,1.86E-02,3.85E-04,1.00E+00,3.00E+00,1.00E+00,732,10,3,2,0,3,1,4.00E+00,1,2.34E-02,0.00E+00,0,0.00E+00
1715158922,,0.00E+00,7.21E+01,2.67E-03,1.35E-07,2.12E-06,4.78E-08,2.67E-03,1.35E-07,4.56E-02,1.02E-03,1.00E+00,3.00E+00,1.00E+01,1172,10,3,3,0,2,1,4.00E+00,1,1.28E-02,0.00E+00,0,0.00E+00
1715159071,,0.00E+00,7.21E+01,2.66E-03,1.81E-07,1.20E-05,4.18E-09,2.66E-03,1.81E-07,2.59E-01,7.32E-05,1.00E+00,3.00E+00,9.98E+01,1878,10,3,4,0,1,1,4.00E+00,1,4.69E-02,0.00E+00,0,0.00E+00
1715159213,,0.00E+00,7.21E+01,2.66E-03,1.32E-07,2.50E-05,1.96E-07,2.66E-03,1.33E-07,5.39E-01,4.20E-03,1.00E+00,3.00E+00,9.97E+02,188,10,3,4,0,0,1,4.00E+00,1,1.07E-02,0.00E+00,0,0.00E+00
1715159670,,0.00E+00,7.41E+01,2.60E-03,3.32E-07,4.05E-07,3.82E-08,2.60E-03,3.32E-07,8.92E-03,8.43E-04,1.00E+00,3.00E+00,1.00E+00,732,10,3,2,0,3,1,4.00E+00,1,1.79E-02,0.00E+00,0,0.00E+00
1715159848,,0.00E+00,7.41E+01,2.60E-03,6.87E-08,1.12E-06,5.53E-09,2.60E-03,6.87E-08,2.48E-02,1.22E-04,1.00E+00,3.00E+00,1.00E+01,1172,10,3,3,0,2,1,4.00E+00,1,2.24E-02,0.00E+00,0,0.00E+00
1715160005,,0.00E+00,7.41E+01,2.59E-03,1.37E-07,9.22E-06,5.31E-08,2.59E-03,1.37E-07,2.04E-01,1.17E-03,1.00E+00,3.00E+00,9.98E+01,1878,10,3,4,0,1,1,4.00E+00,1,1.57E-02,0.00E+00,0,0.00E+00
1715160165,,0.00E+00,7.41E+01,2.59E-03,1.33E-07,1.78E-05,8.46E-08,2.59E-03,1.33E-07,3.94E-01,1.87E-03,1.00E+00,3.00E+00,9.97E+02,188,10,3,4,0,0,1,4.00E+00,1,8.96E-03,0.00E+00,0,0.00E+00
1715160645,,0.00E+00,7.61E+01,2.53E-03,2.90E-07,1.87E-07,3.35E-08,2.53E-03,2.90E-07,4.24E-03,7.58E-04,1.00E+00,3.00E+00,1.00E+00,732,10,3,2,0,3,1,4.00E+00,1,5.87E-02,0.00E+00,0,0.00E+00
1715160826,,0.00E+00,7.60E+01,2.53E-03,1.16E-07,4.81E-07,1.16E-08,2.53E-03,1.16E-07,1.09E-02,2.63E-04,1.00E+00,3.00E+00,1.00E+01,1172,10,3,3,0,2,1,4.00E+00,1,3.05E-02,0.00E+00,0,0.00E+00
1715160998,,0.00E+00,7.61E+01,2.52E-03,3.00E-07,7.07E-06,2.25E-08,2.52E-03,3.00E-07,1.61E-01,5.00E-04,1.00E+00,3.00E+00,9.98E+01,1878,10,3,4,0,1,1,4.00E+00,1,7.05E-03,0.00E+00,0,0.00E+00
1715161141,,0.00E+00,7.60E+01,2.53E-03,3.11E-07,1.18E-05,6.49E-08,2.53E-03,3.11E-07,2.67E-01,1.49E-03,1.00E+00,3.00E+00,9.97E+02,188,10,3,4,0,0,1,4.00E+00,1,6.80E-02,0.00E+00,0,0.00E+00
1715161634,,0.00E+00,7.80E+01,2.47E-03,1.47E-07,-8.74E-08,3.47E-08,2.47E-03,1.47E-07,-2.04E-03,8.06E-04,1.00E+00,3.00E+00,1.00E+00,732,10,3,2,0,3,1,4.00E+00,1,5.41E-02,0.00E+00,0,0.00E+00
1715161818,,0.00E+00,7.80E+01,2.47E-03,2.86E-07,-1.40E-08,3.74E-08,2.47E-03,2.86E-07,-3.36E-04,8.64E-04,1.00E+00,3.00E+00,1.00E+01,1172,10,3,3,0,2,1,4.00E+00,1,1.23E-02,0.00E+00,0,0.00E+00
1715162001,,0.00E+00,7.80E+01,2.46E-03,2.56E-07,5.48E-06,2.70E-08,2.46E-03,2.56E-07,1.28E-01,6.19E-04,1.00E+00,3.00E+00,9.98E+01,1878,10,3,4,0,1,1,4.00E+00,1,3.69E-02,0.00E+00,0,0.00E+00
1715162152,,0.00E+00,7.80E+01,2.47E-03,9.68E-08,7.56E-06,9.74E-08,2.47E-03,9.69E-08,1.75E-01,2.25E-03,1.00E+00,3.00E+00,9.97E+02,188,10,3,4,0,0,1,4.00E+00,1,2.46E-02,0.00E+00,0,0.00E+00
1715162627,,0.00E+00,8.00E+01,2.41E-03,3.60E-07,-2.27E-07,8.16E-08,2.41E-03,3.60E-07,-5.40E-03,1.94E-03,1.00E+00,3.00E+00,1.00E+00,732,10,3,2,0,3,1,4.00E+00,1,3.60E-02,0.00E+00,0,0.00E+00
1715162820,,0.00E+00,8.00E+01,2.40E-03,1.82E-07,-3.70E-07,1.51E-08,2.40E-03,1.82E-07,-8.82E-03,3.58E-04,1.00E+00,3.00E+00,1.00E+01,1172,10,3,3,0,2,1,4.00E+00,1,2.31E-02,0.00E+00,0,0.00E+00
1715162995,,0.00E+00,8.00E+01,2.40E-03,3.18E-07,4.28E-06,2.85E-08,2.40E-03,3.18E-07,1.02E-01,6.89E-04,1.00E+00,3.00E+00,9.98E+01,1878,10,3,4,0,1,1,4.00E+00,1,2.57E-02,0.00E+00,0,0.00E+00
1715163151,,0.00E+00,8.00E+01,2.41E-03,2.49E-07,3.99E-06,6.98E-08,2.41E-03,2.49E-07,9.47E-02,1.66E-03,1.00E+00,3.00E+00,9.97E+02,188,10,3,4,0,0,1,4.00E+00,1,5.15E-03,0.00E+00,0,0.00E+00