File: Magnetic_Nanoparticle_Granulometry/AND100-810-ac4ft-10-300K.ac.dat.csv
[Header],,,,,,,,,,,,,,,,,,,,,,,,,,,
TITLE,MPMS AC Measurement,,,,,,,,,,,,,,,,,,,,,,,,,,
BYAPP,MPMS Measurement,1.1,Summary,,,,,,,,,,,,,,,,,,,,,,,,
FILEOPENTIME, 1713481803.987000 4/18/2024, 5:10:03 PM,,,,,,,,,,,,,,,,,,,,,,,,,
,,,,,,,,,,,,,,,,,,,,,,,,,,,
INFO, APPNAME, MPMS MultiVu Application, Revision 1.61,  Build 082,,,,,,,,,,,,,,,,,,,,,,,
,,,,,,,,,,,,,,,,,,,,,,,,,,,
INFO, NAME, AND100-810,,,,,,,,,,,,,,,,,,,,,,,,,
INFO, WEIGHT,149.41,,,,,,,,,,,,,,,,,,,,,,,,,
INFO, AREA,1,,,,,,,,,,,,,,,,,,,,,,,,,
INFO, LENGTH,1,,,,,,,,,,,,,,,,,,,,,,,,,
INFO, SHAPE,1,,,,,,,,,,,,,,,,,,,,,,,,,
INFO, COMMENT, ,,,,,,,,,,,,,,,,,,,,,,,,,
INFO, SEQUENCE FILE: AC Wakeup.seq,,,,,,,,,,,,,,,,,,,,,,,,,,
,,,,,,,,,,,,,,,,,,,,,,,,,,,
STARTUPAXIS,X,4,LINEAR,AUTO,0,0,,,,,,,,,,,,,,,,,,,,,
STARTUPAXIS,Y1,5,LINEAR,AUTO,0,0,,,,,,,,,,,,,,,,,,,,,
STARTUPAXIS,Y2,7,LINEAR,AUTO,0,0,,,,,,,,,,,,,,,,,,,,,
,,,,,,,,,,,,,,,,,,,,,,,,,,,
,,,,,,,,,,,,,,,,,,,,,,,,,,,
STARTUPGROUP,"m' and m""",,,,,,,,,,,,,,,,,,,,,,,,,,
FIELDGROUP,"m' and m""",1,2,3,4,14,15,5,6,7,8,13,26,27,28,,,,,,,,,,,,
FIELDGROUP,Amplitude and Phase,1,2,3,4,14,15,9,10,11,12,13,26,27,28,,,,,,,,,,,,
,,,,,,,,,,,,,,,,,,,,,,,,,,,
PLOT_APPEARANCE,ALL,HORZ_GRID_ON,VERT_GRID_ON,MARKERS_AND_LINES,,,,,,,,,,,,,,,,,,,,,,,
,,,,,,,,,,,,,,,,,,,,,,,,,,,
[Data],,,,,,,,,,,,,,,,,,,,,,,,,,,
Time,Comment,Field (Oe),Temperature (K),m' (emu),m' Scan Std Dev,"m"" (emu)","m"" Scan Std Dev",Amplitude (emu),Amplitude Scan Std Dev,Phase (deg),Phase Scan Std Dev,Regression Fit,Drive Amplitude (Oe),Wave Frequency (Hz),Steps per Cycle,Blocks to Average,Scans per Measurement,Clock Frequency,Amplifier Gain,AC Filter,Two Point Measurement,Scan Length,Settling Time (sec),Delta Temp (K),Rot Position (Oe),Error,% Clipped
1713482211,,0.00E+00,1.00E+01,3.63E-04,1.90E-07,3.21E-05,2.10E-08,3.64E-04,1.90E-07,5.06E+00,3.50E-03,1.00E+00,3.00E+00,1.00E+00,732,10,3,2,0,3,1,4.00E+00,1,3.18E-03,0.00E+00,0,0.00E+00
1713482404,,0.00E+00,1.00E+01,3.22E-04,1.58E-07,2.37E-05,2.90E-09,3.23E-04,1.58E-07,4.20E+00,2.56E-03,1.00E+00,3.00E+00,1.00E+01,1172,10,3,3,0,2,1,4.00E+00,1,9.47E-04,0.00E+00,0,0.00E+00
1713482566,,0.00E+00,1.00E+01,2.92E-04,1.03E-07,1.74E-05,1.94E-08,2.93E-04,1.03E-07,3.41E+00,3.18E-03,1.00E+00,3.00E+00,9.98E+01,1878,10,3,4,0,1,1,4.00E+00,1,1.89E-03,0.00E+00,0,0.00E+00
1713482724,,0.00E+00,1.00E+01,2.71E-04,1.73E-07,1.12E-05,1.01E-07,2.71E-04,1.74E-07,2.37E+00,2.10E-02,1.00E+00,3.00E+00,9.97E+02,188,10,3,4,0,0,1,4.00E+00,1,9.48E-04,0.00E+00,0,0.00E+00
1713483258,,0.00E+00,1.50E+01,6.79E-04,1.41E-06,1.17E-04,3.02E-07,6.89E-04,1.44E-06,9.82E+00,4.73E-03,1.00E+00,3.00E+00,1.00E+00,732,10,3,2,0,3,1,4.00E+00,1,5.14E-03,0.00E+00,0,0.00E+00
1713483465,,0.00E+00,1.50E+01,5.30E-04,1.27E-07,8.54E-05,2.60E-08,5.37E-04,1.30E-07,9.15E+00,6.56E-04,1.00E+00,3.00E+00,1.00E+01,1172,10,3,3,0,2,1,4.00E+00,1,3.86E-03,0.00E+00,0,0.00E+00
1713483641,,0.00E+00,1.50E+01,4.24E-04,1.33E-07,6.13E-05,3.33E-08,4.28E-04,1.35E-07,8.23E+00,3.22E-03,1.00E+00,3.00E+00,9.98E+01,1878,10,3,4,0,1,1,4.00E+00,1,5.14E-03,0.00E+00,0,0.00E+00
1713483785,,0.00E+00,1.50E+01,3.53E-04,1.57E-07,4.07E-05,1.30E-08,3.55E-04,1.57E-07,6.58E+00,9.00E-04,1.00E+00,3.00E+00,9.97E+02,188,10,3,4,0,0,1,4.00E+00,1,3.85E-03,0.00E+00,0,0.00E+00
1713484312,,0.00E+00,2.00E+01,1.37E-03,3.14E-07,2.88E-04,1.10E-07,1.40E-03,3.30E-07,1.19E+01,1.78E-03,1.00E+00,3.00E+00,1.00E+00,732,10,3,2,0,3,1,4.00E+00,1,6.59E-03,0.00E+00,0,0.00E+00
1713484499,,0.00E+00,2.00E+01,9.98E-04,2.67E-07,2.15E-04,5.31E-08,1.02E-03,2.72E-07,1.22E+01,3.57E-04,1.00E+00,3.00E+00,1.00E+01,1172,10,3,3,0,2,1,4.00E+00,1,5.49E-03,0.00E+00,0,0.00E+00
1713484682,,0.00E+00,2.00E+01,7.28E-04,1.35E-07,1.57E-04,6.23E-08,7.44E-04,1.42E-07,1.22E+01,3.34E-03,1.00E+00,3.00E+00,9.98E+01,1878,10,3,4,0,1,1,4.00E+00,1,3.29E-03,0.00E+00,0,0.00E+00
1713484855,,0.00E+00,2.00E+01,5.42E-04,1.47E-07,1.07E-04,4.01E-08,5.52E-04,1.42E-07,1.12E+01,5.72E-03,1.00E+00,3.00E+00,9.97E+02,188,10,3,4,0,0,1,4.00E+00,1,3.30E-03,0.00E+00,0,0.00E+00
1713485411,,0.00E+00,2.50E+01,2.41E-03,3.31E-07,4.78E-04,7.11E-08,2.46E-03,3.37E-07,1.12E+01,7.87E-04,1.00E+00,3.00E+00,1.00E+00,732,10,3,2,0,3,1,4.00E+00,1,3.27E-03,0.00E+00,0,0.00E+00
1713485596,,0.00E+00,2.50E+01,1.76E-03,6.41E-07,3.92E-04,3.63E-08,1.81E-03,6.33E-07,1.25E+01,3.31E-03,1.00E+00,3.00E+00,1.00E+01,1172,10,3,3,0,2,1,4.00E+00,1,2.46E-03,0.00E+00,0,0.00E+00
1713485771,,0.00E+00,2.50E+01,1.25E-03,2.74E-07,3.04E-04,4.07E-08,1.29E-03,2.76E-07,1.36E+01,1.26E-03,1.00E+00,3.00E+00,9.98E+01,1878,10,3,4,0,1,1,4.00E+00,1,9.01E-03,0.00E+00,0,0.00E+00
1713485977,,0.00E+00,2.50E+01,8.82E-04,8.34E-08,2.17E-04,9.06E-08,9.09E-04,6.65E-08,1.38E+01,6.53E-03,1.00E+00,3.00E+00,9.97E+02,188,10,3,4,0,0,1,4.00E+00,1,1.15E-02,0.00E+00,0,0.00E+00
1713486534,,0.00E+00,3.00E+01,3.46E-03,3.23E-08,5.11E-04,2.84E-08,3.49E-03,3.60E-08,8.40E+00,3.85E-04,1.00E+00,3.00E+00,1.00E+00,732,10,3,2,0,3,1,4.00E+00,1,9.03E-03,0.00E+00,0,0.00E+00
1713486718,,0.00E+00,3.00E+01,2.68E-03,5.90E-07,5.09E-04,1.37E-07,2.73E-03,6.05E-07,1.07E+01,8.19E-04,1.00E+00,3.00E+00,1.00E+01,1172,10,3,3,0,2,1,4.00E+00,1,1.02E-02,0.00E+00,0,0.00E+00
1713486894,,0.00E+00,3.00E+01,1.96E-03,9.05E-07,4.51E-04,2.17E-07,2.01E-03,9.30E-07,1.29E+01,5.54E-04,1.00E+00,3.00E+00,9.98E+01,1878,10,3,4,0,1,1,4.00E+00,1,4.50E-03,0.00E+00,0,0.00E+00
1713487095,,0.00E+00,3.00E+01,1.38E-03,5.83E-07,3.54E-04,2.38E-07,1.42E-03,5.10E-07,1.44E+01,1.49E-02,1.00E+00,3.00E+00,9.97E+02,188,10,3,4,0,0,1,4.00E+00,1,2.26E-03,0.00E+00,0,0.00E+00
1713487655,,0.00E+00,3.50E+01,4.05E-03,7.17E-07,3.77E-04,4.61E-08,4.07E-03,7.18E-07,5.32E+00,5.14E-04,1.00E+00,3.00E+00,1.00E+00,732,10,3,2,0,3,1,4.00E+00,1,7.38E-03,0.00E+00,0,0.00E+00
1713487856,,0.00E+00,3.50E+01,3.42E-03,2.58E-07,4.64E-04,9.73E-08,3.45E-03,2.68E-07,7.74E+00,1.11E-03,1.00E+00,3.00E+00,1.00E+01,1172,10,3,3,0,2,1,4.00E+00,1,7.38E-03,0.00E+00,0,0.00E+00
1713488019,,0.00E+00,3.50E+01,2.68E-03,4.96E-07,5.04E-04,4.95E-08,2.73E-03,4.96E-07,1.06E+01,9.55E-04,1.00E+00,3.00E+00,9.98E+01,1878,10,3,4,0,1,1,4.00E+00,1,7.39E-03,0.00E+00,0,0.00E+00
1713488178,,0.00E+00,3.50E+01,1.97E-03,3.53E-07,4.62E-04,1.10E-07,2.02E-03,3.65E-07,1.32E+01,1.72E-03,1.00E+00,3.00E+00,9.97E+02,188,10,3,4,0,0,1,4.00E+00,1,4.43E-03,0.00E+00,0,0.00E+00
1713488724,,0.00E+00,4.00E+01,4.16E-03,8.71E-07,2.23E-04,2.40E-08,4.16E-03,8.70E-07,3.07E+00,7.51E-04,1.00E+00,3.00E+00,1.00E+00,732,10,3,2,0,3,1,4.00E+00,1,7.48E-03,0.00E+00,0,0.00E+00
1713488914,,0.00E+00,4.00E+01,3.76E-03,1.28E-06,3.26E-04,3.74E-08,3.77E-03,1.28E-06,4.96E+00,1.15E-03,1.00E+00,3.00E+00,1.00E+01,1172,10,3,3,0,2,1,4.00E+00,1,5.60E-03,0.00E+00,0,0.00E+00
1713489094,,0.00E+00,4.00E+01,3.19E-03,6.86E-07,4.34E-04,8.70E-08,3.22E-03,6.86E-07,7.74E+00,1.59E-03,1.00E+00,3.00E+00,9.98E+01,1878,10,3,4,0,1,1,4.00E+00,1,1.31E-02,0.00E+00,0,0.00E+00
1713489266,,0.00E+00,4.00E+01,2.52E-03,7.17E-07,4.81E-04,1.08E-07,2.56E-03,7.23E-07,1.08E+01,9.89E-04,1.00E+00,3.00E+00,9.97E+02,188,10,3,4,0,0,1,4.00E+00,1,9.35E-03,0.00E+00,0,0.00E+00
1713489785,,0.00E+00,4.50E+01,3.99E-03,8.53E-07,1.15E-04,5.29E-08,3.99E-03,8.54E-07,1.66E+00,4.45E-04,1.00E+00,3.00E+00,1.00E+00,732,10,3,2,0,3,1,4.00E+00,1,1.15E-02,0.00E+00,0,0.00E+00
1713489987,,0.00E+00,4.50E+01,3.77E-03,3.77E-07,1.95E-04,6.15E-08,3.78E-03,3.74E-07,2.96E+00,1.21E-03,1.00E+00,3.00E+00,1.00E+01,1172,10,3,3,0,2,1,4.00E+00,1,2.31E-03,0.00E+00,0,0.00E+00
1713490164,,0.00E+00,4.50E+01,3.41E-03,4.38E-07,3.09E-04,2.37E-08,3.42E-03,4.37E-07,5.19E+00,6.85E-04,1.00E+00,3.00E+00,9.98E+01,1878,10,3,4,0,1,1,4.00E+00,1,1.61E-02,0.00E+00,0,0.00E+00
1713490347,,0.00E+00,4.50E+01,2.89E-03,6.20E-07,4.11E-04,6.36E-08,2.92E-03,6.23E-07,8.09E+00,5.91E-04,1.00E+00,3.00E+00,9.97E+02,188,10,3,4,0,0,1,4.00E+00,1,1.15E-02,0.00E+00,0,0.00E+00
1713490867,,0.00E+00,5.00E+01,3.72E-03,6.31E-07,5.45E-05,3.06E-08,3.72E-03,6.32E-07,8.40E-01,4.32E-04,1.00E+00,3.00E+00,1.00E+00,732,10,3,2,0,3,1,4.00E+00,1,3.33E-02,0.00E+00,0,0.00E+00
1713491045,,0.00E+00,5.00E+01,3.61E-03,4.18E-07,1.04E-04,5.42E-08,3.61E-03,4.17E-07,1.66E+00,1.04E-03,1.00E+00,3.00E+00,1.00E+01,1172,10,3,3,0,2,1,4.00E+00,1,1.67E-02,0.00E+00,0,0.00E+00
1713491218,,0.00E+00,5.00E+01,3.40E-03,5.57E-07,1.95E-04,7.37E-08,3.40E-03,5.52E-07,3.29E+00,1.76E-03,1.00E+00,3.00E+00,9.98E+01,1878,10,3,4,0,1,1,4.00E+00,1,1.39E-02,0.00E+00,0,0.00E+00
1713491392,,0.00E+00,5.00E+01,3.06E-03,6.41E-07,3.03E-04,8.69E-08,3.08E-03,6.29E-07,5.66E+00,2.79E-03,1.00E+00,3.00E+00,9.97E+02,188,10,3,4,0,0,1,4.00E+00,1,1.39E-02,0.00E+00,0,0.00E+00
1713491912,,0.00E+00,5.50E+01,3.43E-03,6.08E-07,2.39E-05,2.34E-08,3.43E-03,6.08E-07,4.00E-01,3.82E-04,1.00E+00,3.00E+00,1.00E+00,732,10,3,2,0,3,1,4.00E+00,1,1.45E-02,0.00E+00,0,0.00E+00
1713492103,,0.00E+00,5.50E+01,3.38E-03,1.41E-07,5.12E-05,6.92E-08,3.38E-03,1.41E-07,8.69E-01,1.19E-03,1.00E+00,3.00E+00,1.00E+01,1172,10,3,3,0,2,1,4.00E+00,1,1.18E-02,0.00E+00,0,0.00E+00
1713492272,,0.00E+00,5.50E+01,3.27E-03,3.81E-07,1.13E-04,6.15E-08,3.27E-03,3.81E-07,1.98E+00,1.14E-03,1.00E+00,3.00E+00,9.98E+01,1878,10,3,4,0,1,1,4.00E+00,1,2.89E-02,0.00E+00,0,0.00E+00
1713492421,,0.00E+00,5.50E+01,3.07E-03,6.21E-07,2.01E-04,2.14E-08,3.08E-03,6.19E-07,3.74E+00,1.03E-03,1.00E+00,3.00E+00,9.97E+02,188,10,3,4,0,0,1,4.00E+00,1,1.97E-02,0.00E+00,0,0.00E+00
1713492956,,0.00E+00,6.00E+01,3.16E-03,4.43E-07,1.00E-05,1.83E-08,3.16E-03,4.43E-07,1.81E-01,3.43E-04,1.00E+00,3.00E+00,1.00E+00,732,10,3,2,0,3,1,4.00E+00,1,2.46E-02,0.00E+00,0,0.00E+00
1713493144,,0.00E+00,6.00E+01,3.14E-03,3.81E-07,2.33E-05,3.95E-08,3.14E-03,3.81E-07,4.26E-01,7.64E-04,1.00E+00,3.00E+00,1.00E+01,1172,10,3,3,0,2,1,4.00E+00,1,2.92E-02,0.00E+00,0,0.00E+00
1713493312,,0.00E+00,6.00E+01,3.08E-03,6.79E-08,6.14E-05,4.92E-08,3.08E-03,6.72E-08,1.14E+00,9.32E-04,1.00E+00,3.00E+00,9.98E+01,1878,10,3,4,0,1,1,4.00E+00,1,1.08E-02,0.00E+00,0,0.00E+00
1713493436,,0.00E+00,6.00E+01,2.98E-03,1.09E-07,1.21E-04,6.40E-08,2.98E-03,1.10E-07,2.33E+00,1.21E-03,1.00E+00,3.00E+00,9.97E+02,188,10,3,4,0,0,1,4.00E+00,1,9.22E-03,0.00E+00,0,0.00E+00
1713493947,,0.00E+00,6.50E+01,2.92E-03,6.60E-07,3.87E-06,2.08E-08,2.92E-03,6.60E-07,7.60E-02,4.25E-04,1.00E+00,3.00E+00,1.00E+00,732,10,3,2,0,3,1,4.00E+00,1,2.48E-02,0.00E+00,0,0.00E+00
1713494121,,0.00E+00,6.50E+01,2.91E-03,1.70E-07,9.62E-06,5.75E-08,2.91E-03,1.69E-07,1.89E-01,1.13E-03,1.00E+00,3.00E+00,1.00E+01,1172,10,3,3,0,2,1,4.00E+00,1,2.30E-02,0.00E+00,0,0.00E+00
1713494293,,0.00E+00,6.50E+01,2.88E-03,3.27E-07,3.19E-05,3.30E-08,2.88E-03,3.27E-07,6.34E-01,6.05E-04,1.00E+00,3.00E+00,9.98E+01,1878,10,3,4,0,1,1,4.00E+00,1,1.95E-02,0.00E+00,0,0.00E+00
1713494429,,0.00E+00,6.50E+01,2.84E-03,1.63E-07,6.71E-05,8.23E-08,2.84E-03,1.64E-07,1.35E+00,1.61E-03,1.00E+00,3.00E+00,9.97E+02,188,10,3,4,0,0,1,4.00E+00,1,1.60E-02,0.00E+00,0,0.00E+00
1713494977,,0.00E+00,7.00E+01,2.71E-03,6.30E-07,1.29E-06,5.68E-08,2.71E-03,6.30E-07,2.73E-02,1.20E-03,1.00E+00,3.00E+00,1.00E+00,732,10,3,2,0,3,1,4.00E+00,1,2.83E-02,0.00E+00,0,0.00E+00
1713495156,,0.00E+00,7.00E+01,2.70E-03,3.42E-08,3.24E-06,2.36E-08,2.70E-03,3.42E-08,6.86E-02,4.99E-04,1.00E+00,3.00E+00,1.00E+01,1172,10,3,3,0,2,1,4.00E+00,1,4.25E-02,0.00E+00,0,0.00E+00
1713495313,,0.00E+00,7.00E+01,2.69E-03,1.97E-07,1.61E-05,1.99E-08,2.69E-03,1.97E-07,3.42E-01,4.44E-04,1.00E+00,3.00E+00,9.98E+01,1878,10,3,4,0,1,1,4.00E+00,1,2.23E-02,0.00E+00,0,0.00E+00
1713495470,,0.00E+00,7.00E+01,2.68E-03,7.08E-08,3.31E-05,1.24E-07,2.68E-03,6.96E-08,7.07E-01,2.67E-03,1.00E+00,3.00E+00,9.97E+02,188,10,3,4,0,0,1,4.00E+00,1,4.25E-02,0.00E+00,0,0.00E+00
1713495967,,0.00E+00,7.50E+01,2.53E-03,6.99E-07,2.19E-07,6.12E-08,2.53E-03,6.99E-07,4.96E-03,1.38E-03,1.00E+00,3.00E+00,1.00E+00,732,10,3,2,0,3,1,4.00E+00,1,1.37E-02,0.00E+00,0,0.00E+00
1713496148,,0.00E+00,7.50E+01,2.53E-03,2.29E-07,4.19E-07,5.30E-08,2.53E-03,2.29E-07,9.50E-03,1.20E-03,1.00E+00,3.00E+00,1.00E+01,1172,10,3,3,0,2,1,4.00E+00,1,1.60E-02,0.00E+00,0,0.00E+00
1713496305,,0.00E+00,7.50E+01,2.52E-03,2.91E-07,8.01E-06,3.68E-08,2.52E-03,2.91E-07,1.82E-01,8.17E-04,1.00E+00,3.00E+00,9.98E+01,1878,10,3,4,0,1,1,4.00E+00,1,3.89E-02,0.00E+00,0,0.00E+00
1713496470,,0.00E+00,7.50E+01,2.53E-03,1.03E-07,1.36E-05,6.95E-08,2.53E-03,1.03E-07,3.08E-01,1.58E-03,1.00E+00,3.00E+00,9.97E+02,188,10,3,4,0,0,1,4.00E+00,1,3.20E-02,0.00E+00,0,0.00E+00
1713496966,,0.00E+00,8.00E+01,2.37E-03,5.41E-07,-2.90E-07,1.97E-08,2.37E-03,5.41E-07,-6.99E-03,4.69E-04,1.00E+00,3.00E+00,1.00E+00,732,10,3,2,0,3,1,4.00E+00,1,4.37E-02,0.00E+00,0,0.00E+00
1713497144,,0.00E+00,8.00E+01,2.37E-03,1.63E-07,-7.48E-07,2.87E-08,2.37E-03,1.63E-07,-1.81E-02,6.87E-04,1.00E+00,3.00E+00,1.00E+01,1172,10,3,3,0,2,1,4.00E+00,1,4.11E-02,0.00E+00,0,0.00E+00
1713497303,,0.00E+00,8.00E+01,2.36E-03,3.53E-07,4.05E-06,3.82E-08,2.36E-03,3.53E-07,9.81E-02,9.14E-04,1.00E+00,3.00E+00,9.98E+01,1878,10,3,4,0,1,1,4.00E+00,1,1.80E-02,0.00E+00,0,0.00E+00
1713497491,,0.00E+00,8.00E+01,2.38E-03,2.39E-07,2.98E-06,2.05E-07,2.38E-03,2.39E-07,7.18E-02,4.93E-03,1.00E+00,3.00E+00,9.97E+02,188,10,3,4,0,0,1,4.00E+00,1,9.25E-02,0.00E+00,0,0.00E+00
1713497992,,0.00E+00,8.50E+01,2.23E-03,4.28E-07,-5.19E-07,4.27E-08,2.23E-03,4.28E-07,-1.33E-02,1.10E-03,1.00E+00,3.00E+00,1.00E+00,732,10,3,2,0,3,1,4.00E+00,1,2.29E-02,0.00E+00,0,0.00E+00
1713498172,,0.00E+00,8.50E+01,2.23E-03,3.00E-07,-1.19E-06,2.38E-08,2.23E-03,3.00E-07,-3.05E-02,6.14E-04,1.00E+00,3.00E+00,1.00E+01,1172,10,3,3,0,2,1,4.00E+00,1,2.57E-02,0.00E+00,0,0.00E+00
1713498329,,0.00E+00,8.50E+01,2.23E-03,3.91E-07,2.20E-06,2.85E-08,2.23E-03,3.91E-07,5.66E-02,7.27E-04,1.00E+00,3.00E+00,9.98E+01,1878,10,3,4,0,1,1,4.00E+00,1,2.00E-02,0.00E+00,0,0.00E+00
1713498474,,0.00E+00,8.50E+01,2.24E-03,4.13E-07,-2.59E-06,3.98E-08,2.24E-03,4.13E-07,-6.62E-02,1.01E-03,1.00E+00,3.00E+00,9.97E+02,188,10,3,4,0,0,1,4.00E+00,1,8.58E-03,0.00E+00,0,0.00E+00
1713498975,,0.00E+00,9.00E+01,2.11E-03,4.96E-07,-5.65E-07,1.07E-07,2.11E-03,4.96E-07,-1.54E-02,2.89E-03,1.00E+00,3.00E+00,1.00E+00,732,10,3,2,0,3,1,4.00E+00,1,1.58E-02,0.00E+00,0,0.00E+00
1713499158,,0.00E+00,9.00E+01,2.10E-03,1.93E-07,-1.44E-06,2.73E-08,2.10E-03,1.93E-07,-3.91E-02,7.50E-04,1.00E+00,3.00E+00,1.00E+01,1172,10,3,3,0,2,1,4.00E+00,1,2.53E-02,0.00E+00,0,0.00E+00
1713499312,,0.00E+00,9.00E+01,2.10E-03,3.33E-07,1.25E-06,3.01E-08,2.10E-03,3.34E-07,3.40E-02,8.18E-04,1.00E+00,3.00E+00,9.98E+01,1878,10,3,4,0,1,1,4.00E+00,1,2.53E-02,0.00E+00,0,0.00E+00
1713499470,,0.00E+00,9.00E+01,2.12E-03,5.06E-07,-5.32E-06,6.99E-08,2.12E-03,5.06E-07,-1.44E-01,1.91E-03,1.00E+00,3.00E+00,9.97E+02,188,10,3,4,0,0,1,4.00E+00,1,1.27E-02,0.00E+00,0,0.00E+00
1713499972,,0.00E+00,9.50E+01,2.00E-03,3.81E-07,-5.08E-07,3.00E-08,2.00E-03,3.81E-07,-1.46E-02,8.61E-04,1.00E+00,3.00E+00,1.00E+00,732,10,3,2,0,3,1,4.00E+00,1,1.05E-02,0.00E+00,0,0.00E+00
1713500157,,0.00E+00,9.50E+01,1.99E-03,1.39E-07,-1.60E-06,1.67E-08,1.99E-03,1.39E-07,-4.61E-02,4.84E-04,1.00E+00,3.00E+00,1.00E+01,1172,10,3,3,0,2,1,4.00E+00,1,6.97E-02,0.00E+00,0,0.00E+00
1713500314,,0.00E+00,9.50E+01,1.99E-03,3.50E-07,7.87E-07,1.16E-08,1.99E-03,3.50E-07,2.26E-02,3.31E-04,1.00E+00,3.00E+00,9.98E+01,1878,10,3,4,0,1,1,4.00E+00,1,4.18E-02,0.00E+00,0,0.00E+00
1713500497,,0.00E+00,9.50E+01,2.01E-03,4.72E-07,-6.89E-06,4.37E-08,2.01E-03,4.72E-07,-1.96E-01,1.22E-03,1.00E+00,3.00E+00,9.97E+02,188,10,3,4,0,0,1,4.00E+00,1,6.28E-02,0.00E+00,0,0.00E+00
1713501026,,0.00E+00,1.00E+02,1.90E-03,5.30E-07,-3.92E-07,2.35E-08,1.90E-03,5.30E-07,-1.19E-02,7.08E-04,1.00E+00,3.00E+00,1.00E+00,732,10,3,2,0,3,1,4.00E+00,1,3.06E-02,0.00E+00,0,0.00E+00
1713501223,,0.00E+00,1.00E+02,1.89E-03,5.08E-07,-1.65E-06,3.16E-08,1.89E-03,5.08E-07,-4.99E-02,9.75E-04,1.00E+00,3.00E+00,1.00E+01,1172,10,3,3,0,2,1,4.00E+00,1,3.05E-02,0.00E+00,0,0.00E+00
1713501401,,0.00E+00,1.00E+02,1.89E-03,3.75E-07,6.14E-07,5.22E-08,1.89E-03,3.75E-07,1.86E-02,1.58E-03,1.00E+00,3.00E+00,9.98E+01,1878,10,3,4,0,1,1,4.00E+00,1,8.78E-02,0.00E+00,0,0.00E+00
1713501569,,0.00E+00,1.00E+02,1.91E-03,2.42E-07,-7.49E-06,4.71E-08,1.91E-03,2.42E-07,-2.25E-01,1.41E-03,1.00E+00,3.00E+00,9.97E+02,188,10,3,4,0,0,1,4.00E+00,1,1.53E-02,0.00E+00,0,0.00E+00
1713502105,,0.00E+00,1.05E+02,1.80E-03,3.30E-07,-4.00E-07,3.11E-08,1.80E-03,3.30E-07,-1.27E-02,9.96E-04,1.00E+00,3.00E+00,1.00E+00,732,10,3,2,0,3,1,4.00E+00,1,1.16E-01,0.00E+00,0,0.00E+00
1713502309,,0.00E+00,1.05E+02,1.80E-03,3.57E-07,-1.72E-06,1.53E-08,1.80E-03,3.57E-07,-5.47E-02,5.04E-04,1.00E+00,3.00E+00,1.00E+01,1172,10,3,3,0,2,1,4.00E+00,1,3.32E-02,0.00E+00,0,0.00E+00
1713502472,,0.00E+00,1.05E+02,1.80E-03,3.47E-07,5.02E-07,8.10E-09,1.80E-03,3.47E-07,1.59E-02,2.57E-04,1.00E+00,3.00E+00,9.98E+01,1878,10,3,4,0,1,1,4.00E+00,1,4.15E-02,0.00E+00,0,0.00E+00
1713502635,,0.00E+00,1.05E+02,1.82E-03,3.39E-07,-7.72E-06,1.70E-07,1.82E-03,3.39E-07,-2.43E-01,5.32E-03,1.00E+00,3.00E+00,9.97E+02,188,10,3,4,0,0,1,4.00E+00,1,5.81E-02,0.00E+00,0,0.00E+00
1713503138,,0.00E+00,1.10E+02,1.72E-03,6.60E-07,-2.42E-07,6.64E-08,1.72E-03,6.60E-07,-8.06E-03,2.21E-03,1.00E+00,3.00E+00,1.00E+00,732,10,3,2,0,3,1,4.00E+00,1,9.44E-02,0.00E+00,0,0.00E+00
1713503321,,0.00E+00,1.10E+02,1.72E-03,7.11E-08,-1.75E-06,5.11E-08,1.72E-03,7.11E-08,-5.83E-02,1.71E-03,1.00E+00,3.00E+00,1.00E+01,1172,10,3,3,0,2,1,4.00E+00,1,1.53E-01,0.00E+00,0,0.00E+00
1713503484,,0.00E+00,1.10E+02,1.72E-03,3.01E-07,4.02E-07,3.01E-08,1.72E-03,3.01E-07,1.34E-02,1.00E-03,1.00E+00,3.00E+00,9.98E+01,1878,10,3,4,0,1,1,4.00E+00,1,5.39E-02,0.00E+00,0,0.00E+00
1713503653,,0.00E+00,1.10E+02,1.74E-03,2.32E-07,-7.73E-06,3.78E-08,1.74E-03,2.32E-07,-2.55E-01,1.27E-03,1.00E+00,3.00E+00,9.97E+02,188,10,3,4,0,0,1,4.00E+00,1,4.49E-02,0.00E+00,0,0.00E+00
1713504153,,0.00E+00,1.15E+02,1.64E-03,7.24E-07,-2.84E-07,8.85E-08,1.64E-03,7.24E-07,-9.92E-03,3.09E-03,1.00E+00,3.00E+00,1.00E+00,732,10,3,2,0,3,1,4.00E+00,1,1.95E-02,0.00E+00,0,0.00E+00
1713504336,,0.00E+00,1.15E+02,1.64E-03,2.92E-07,-1.71E-06,5.49E-08,1.64E-03,2.92E-07,-5.98E-02,1.91E-03,1.00E+00,3.00E+00,1.00E+01,1172,10,3,3,0,2,1,4.00E+00,1,2.43E-02,0.00E+00,0,0.00E+00
1713504499,,0.00E+00,1.15E+02,1.64E-03,4.99E-07,3.88E-07,1.64E-08,1.64E-03,4.99E-07,1.35E-02,5.71E-04,1.00E+00,3.00E+00,9.98E+01,1878,10,3,4,0,1,1,4.00E+00,1,5.35E-02,0.00E+00,0,0.00E+00
1713504678,,0.00E+00,1.15E+02,1.66E-03,4.13E-07,-7.65E-06,6.26E-08,1.66E-03,4.13E-07,-2.65E-01,2.23E-03,1.00E+00,3.00E+00,9.97E+02,188,10,3,4,0,0,1,4.00E+00,1,1.46E-02,0.00E+00,0,0.00E+00
1713505199,,0.00E+00,1.20E+02,1.57E-03,5.32E-07,-2.42E-07,3.26E-08,1.57E-03,5.32E-07,-8.85E-03,1.20E-03,1.00E+00,3.00E+00,1.00E+00,732,10,3,2,0,3,1,4.00E+00,1,6.84E-02,0.00E+00,0,0.00E+00
1713505410,,0.00E+00,1.20E+02,1.57E-03,1.66E-07,-1.70E-06,1.87E-08,1.57E-03,1.66E-07,-6.18E-02,6.88E-04,1.00E+00,3.00E+00,1.00E+01,1172,10,3,3,0,2,1,4.00E+00,1,7.89E-02,0.00E+00,0,0.00E+00
1713505583,,0.00E+00,1.20E+02,1.57E-03,3.86E-07,3.51E-07,9.87E-09,1.57E-03,3.86E-07,1.28E-02,3.57E-04,1.00E+00,3.00E+00,9.98E+01,1878,10,3,4,0,1,1,4.00E+00,1,5.79E-02,0.00E+00,0,0.00E+00
1713505765,,0.00E+00,1.20E+02,1.59E-03,5.98E-07,-7.50E-06,1.80E-07,1.59E-03,5.98E-07,-2.71E-01,6.43E-03,1.00E+00,3.00E+00,9.97E+02,188,10,3,4,0,0,1,4.00E+00,1,7.89E-02,0.00E+00,0,0.00E+00
1713506262,,0.00E+00,1.25E+02,1.51E-03,2.21E-07,-2.65E-07,2.21E-08,1.51E-03,2.21E-07,-1.01E-02,8.48E-04,1.00E+00,3.00E+00,1.00E+00,732,10,3,2,0,3,1,4.00E+00,1,9.64E-02,0.00E+00,0,0.00E+00
1713506445,,0.00E+00,1.25E+02,1.51E-03,3.04E-07,-1.67E-06,1.80E-09,1.51E-03,3.04E-07,-6.37E-02,6.47E-05,1.00E+00,3.00E+00,1.00E+01,1172,10,3,3,0,2,1,4.00E+00,1,6.24E-02,0.00E+00,0,0.00E+00
1713506620,,0.00E+00,1.25E+02,1.51E-03,4.63E-07,3.28E-07,3.56E-08,1.51E-03,4.63E-07,1.25E-02,1.36E-03,1.00E+00,3.00E+00,9.98E+01,1878,10,3,4,0,1,1,4.00E+00,1,1.93E-01,0.00E+00,0,0.00E+00
1713506775,,0.00E+00,1.25E+02,1.52E-03,3.45E-07,-7.25E-06,1.41E-07,1.52E-03,3.45E-07,-2.73E-01,5.29E-03,1.00E+00,3.00E+00,9.97E+02,188,10,3,4,0,0,1,4.00E+00,1,4.53E-02,0.00E+00,0,0.00E+00
1713507263,,0.00E+00,1.30E+02,1.45E-03,3.51E-07,-2.29E-07,5.41E-08,1.45E-03,3.51E-07,-9.09E-03,2.14E-03,1.00E+00,3.00E+00,1.00E+00,732,10,3,2,0,3,1,4.00E+00,1,9.14E-02,0.00E+00,0,0.00E+00
1713507453,,0.00E+00,1.30E+02,1.45E-03,3.42E-07,-1.66E-06,1.99E-08,1.45E-03,3.42E-07,-6.60E-02,8.03E-04,1.00E+00,3.00E+00,1.00E+01,1172,10,3,3,0,2,1,4.00E+00,1,5.48E-02,0.00E+00,0,0.00E+00
1713507626,,0.00E+00,1.30E+02,1.45E-03,4.71E-07,3.11E-07,2.21E-08,1.45E-03,4.71E-07,1.23E-02,8.75E-04,1.00E+00,3.00E+00,9.98E+01,1878,10,3,4,0,1,1,4.00E+00,1,9.75E-02,0.00E+00,0,0.00E+00
1713507795,,0.00E+00,1.30E+02,1.46E-03,4.57E-07,-6.95E-06,1.08E-07,1.46E-03,4.57E-07,-2.73E-01,4.22E-03,1.00E+00,3.00E+00,9.97E+02,188,10,3,4,0,0,1,4.00E+00,1,6.70E-02,0.00E+00,0,0.00E+00
1713508296,,0.00E+00,1.35E+02,1.39E-03,4.09E-07,-3.27E-07,9.53E-09,1.39E-03,4.09E-07,-1.35E-02,3.87E-04,1.00E+00,3.00E+00,1.00E+00,732,10,3,2,0,3,1,4.00E+00,1,9.15E-02,0.00E+00,0,0.00E+00
1713508482,,0.00E+00,1.35E+02,1.39E-03,3.35E-07,-1.63E-06,2.26E-08,1.39E-03,3.35E-07,-6.72E-02,9.36E-04,1.00E+00,3.00E+00,1.00E+01,1172,10,3,3,0,2,1,4.00E+00,1,3.92E-02,0.00E+00,0,0.00E+00
1713508660,,0.00E+00,1.35E+02,1.39E-03,3.66E-07,3.10E-07,2.50E-08,1.39E-03,3.66E-07,1.28E-02,1.03E-03,1.00E+00,3.00E+00,9.98E+01,1878,10,3,4,0,1,1,4.00E+00,1,6.54E-02,0.00E+00,0,0.00E+00
1713508870,,0.00E+00,1.35E+02,1.40E-03,5.84E-07,-6.73E-06,1.39E-07,1.40E-03,5.83E-07,-2.75E-01,5.75E-03,1.00E+00,3.00E+00,9.97E+02,188,10,3,4,0,0,1,4.00E+00,1,6.54E-02,0.00E+00,0,0.00E+00
1713509445,,0.00E+00,1.40E+02,1.34E-03,7.99E-07,-2.88E-07,6.73E-09,1.34E-03,7.99E-07,-1.24E-02,2.84E-04,1.00E+00,3.00E+00,1.00E+00,732,10,3,2,0,3,1,4.00E+00,1,6.29E-02,0.00E+00,0,0.00E+00
1713509627,,0.00E+00,1.40E+02,1.34E-03,3.05E-07,-1.58E-06,1.03E-08,1.34E-03,3.05E-07,-6.77E-02,4.34E-04,1.00E+00,3.00E+00,1.00E+01,1172,10,3,3,0,2,1,4.00E+00,1,6.29E-02,0.00E+00,0,0.00E+00
1713509783,,0.00E+00,1.40E+02,1.34E-03,4.25E-07,1.96E-07,1.58E-08,1.34E-03,4.25E-07,8.42E-03,6.81E-04,1.00E+00,3.00E+00,9.98E+01,1878,10,3,4,0,1,1,4.00E+00,1,4.89E-02,0.00E+00,0,0.00E+00
1713509940,,0.00E+00,1.40E+02,1.35E-03,5.21E-07,-7.21E-06,7.06E-08,1.35E-03,5.21E-07,-3.06E-01,2.98E-03,1.00E+00,3.00E+00,9.97E+02,188,10,3,4,0,0,1,4.00E+00,1,3.49E-02,0.00E+00,0,0.00E+00
1713510446,,0.00E+00,1.45E+02,1.29E-03,4.56E-07,-2.75E-07,3.36E-08,1.29E-03,4.56E-07,-1.23E-02,1.50E-03,1.00E+00,3.00E+00,1.00E+00,732,10,3,2,0,3,1,4.00E+00,1,5.96E-02,0.00E+00,0,0.00E+00
1713510628,,0.00E+00,1.45E+02,1.29E-03,3.72E-07,-1.53E-06,2.86E-08,1.29E-03,3.72E-07,-6.82E-02,1.28E-03,1.00E+00,3.00E+00,1.00E+01,1172,10,3,3,0,2,1,4.00E+00,1,1.19E-01,0.00E+00,0,0.00E+00
1713510789,,0.00E+00,1.45E+02,1.29E-03,4.80E-07,1.47E-07,3.36E-08,1.29E-03,4.80E-07,6.54E-03,1.50E-03,1.00E+00,3.00E+00,9.98E+01,1878,10,3,4,0,1,1,4.00E+00,1,4.48E-02,0.00E+00,0,0.00E+00
1713510956,,0.00E+00,1.45E+02,1.30E-03,4.75E-07,-6.99E-06,3.21E-08,1.30E-03,4.75E-07,-3.08E-01,1.38E-03,1.00E+00,3.00E+00,9.97E+02,188,10,3,4,0,0,1,4.00E+00,1,2.98E-02,0.00E+00,0,0.00E+00
1713511490,,0.00E+00,1.50E+02,1.24E-03,6.18E-07,-3.18E-07,2.50E-08,1.24E-03,6.18E-07,-1.47E-02,1.16E-03,1.00E+00,3.00E+00,1.00E+00,732,10,3,2,0,3,1,4.00E+00,1,1.11E-01,0.00E+00,0,0.00E+00
1713511673,,0.00E+00,1.50E+02,1.24E-03,3.83E-07,-1.46E-06,2.69E-08,1.24E-03,3.83E-07,-6.75E-02,1.26E-03,1.00E+00,3.00E+00,1.00E+01,1172,10,3,3,0,2,1,4.00E+00,1,1.11E-01,0.00E+00,0,0.00E+00
1713511835,,0.00E+00,1.50E+02,1.24E-03,4.91E-07,1.19E-07,7.86E-09,1.24E-03,4.91E-07,5.53E-03,3.65E-04,1.00E+00,3.00E+00,9.98E+01,1878,10,3,4,0,1,1,4.00E+00,1,3.96E-02,0.00E+00,0,0.00E+00
1713511992,,0.00E+00,1.50E+02,1.25E-03,2.93E-07,-6.66E-06,1.06E-07,1.25E-03,2.93E-07,-3.05E-01,4.82E-03,1.00E+00,3.00E+00,9.97E+02,188,10,3,4,0,0,1,4.00E+00,1,1.03E-01,0.00E+00,0,0.00E+00
1713512540,,0.00E+00,1.55E+02,1.19E-03,4.26E-07,-3.33E-07,3.54E-08,1.19E-03,4.26E-07,-1.60E-02,1.71E-03,1.00E+00,3.00E+00,1.00E+00,732,10,3,2,0,3,1,4.00E+00,1,1.25E-02,0.00E+00,0,0.00E+00
1713512717,,0.00E+00,1.55E+02,1.19E-03,4.05E-07,-1.41E-06,1.17E-08,1.19E-03,4.05E-07,-6.78E-02,5.50E-04,1.00E+00,3.00E+00,1.00E+01,1172,10,3,3,0,2,1,4.00E+00,1,1.68E-02,0.00E+00,0,0.00E+00
1713512891,,0.00E+00,1.55E+02,1.19E-03,3.62E-07,1.17E-07,9.85E-09,1.19E-03,3.62E-07,5.60E-03,4.72E-04,1.00E+00,3.00E+00,9.98E+01,1878,10,3,4,0,1,1,4.00E+00,1,1.26E-02,0.00E+00,0,0.00E+00
1713513070,,0.00E+00,1.55E+02,1.21E-03,3.46E-07,-6.43E-06,2.45E-08,1.21E-03,3.46E-07,-3.06E-01,1.24E-03,1.00E+00,3.00E+00,9.97E+02,188,10,3,4,0,0,1,4.00E+00,1,1.26E-02,0.00E+00,0,0.00E+00
1713513610,,0.00E+00,1.60E+02,1.15E-03,4.59E-07,-3.49E-07,2.23E-08,1.15E-03,4.59E-07,-1.74E-02,1.10E-03,1.00E+00,3.00E+00,1.00E+00,732,10,3,2,0,3,1,4.00E+00,1,8.90E-03,0.00E+00,0,0.00E+00
1713513790,,0.00E+00,1.60E+02,1.15E-03,3.93E-07,-1.35E-06,1.94E-09,1.15E-03,3.93E-07,-6.71E-02,7.16E-05,1.00E+00,3.00E+00,1.00E+01,1172,10,3,3,0,2,1,4.00E+00,1,1.33E-02,0.00E+00,0,0.00E+00
1713513962,,0.00E+00,1.60E+02,1.15E-03,3.91E-07,7.31E-08,3.59E-08,1.15E-03,3.91E-07,3.64E-03,1.79E-03,1.00E+00,3.00E+00,9.98E+01,1878,10,3,4,0,1,1,4.00E+00,1,8.90E-03,0.00E+00,0,0.00E+00
1713514137,,0.00E+00,1.60E+02,1.16E-03,3.96E-07,-6.35E-06,7.03E-08,1.16E-03,3.96E-07,-3.13E-01,3.39E-03,1.00E+00,3.00E+00,9.97E+02,188,10,3,4,0,0,1,4.00E+00,1,8.90E-03,0.00E+00,0,0.00E+00
1713514660,,0.00E+00,1.65E+02,1.11E-03,5.23E-07,-3.36E-07,1.82E-08,1.11E-03,5.23E-07,-1.73E-02,9.36E-04,1.00E+00,3.00E+00,1.00E+00,732,10,3,2,0,3,1,4.00E+00,1,1.40E-02,0.00E+00,0,0.00E+00
1713514839,,0.00E+00,1.65E+02,1.11E-03,3.44E-07,-1.28E-06,1.51E-08,1.11E-03,3.44E-07,-6.61E-02,7.65E-04,1.00E+00,3.00E+00,1.00E+01,1172,10,3,3,0,2,1,4.00E+00,1,1.40E-02,0.00E+00,0,0.00E+00
1713515009,,0.00E+00,1.65E+02,1.11E-03,3.84E-07,5.21E-08,5.23E-09,1.11E-03,3.84E-07,2.69E-03,2.69E-04,1.00E+00,3.00E+00,9.98E+01,1878,10,3,4,0,1,1,4.00E+00,1,1.40E-02,0.00E+00,0,0.00E+00
1713515207,,0.00E+00,1.65E+02,1.12E-03,4.22E-07,-6.09E-06,2.97E-08,1.12E-03,4.22E-07,-3.11E-01,1.43E-03,1.00E+00,3.00E+00,9.97E+02,188,10,3,4,0,0,1,4.00E+00,1,2.34E-02,0.00E+00,0,0.00E+00
1713515711,,0.00E+00,1.70E+02,1.07E-03,5.26E-07,-3.38E-07,3.74E-08,1.07E-03,5.26E-07,-1.80E-02,2.01E-03,1.00E+00,3.00E+00,1.00E+00,732,10,3,2,0,3,1,4.00E+00,1,1.99E-02,0.00E+00,0,0.00E+00
1713515873,,0.00E+00,1.70E+02,1.07E-03,3.90E-07,-1.22E-06,2.59E-08,1.07E-03,3.90E-07,-6.54E-02,1.40E-03,1.00E+00,3.00E+00,1.00E+01,1172,10,3,3,0,2,1,4.00E+00,1,1.98E-02,0.00E+00,0,0.00E+00
1713516057,,0.00E+00,1.70E+02,1.07E-03,3.84E-07,2.16E-08,3.57E-08,1.07E-03,3.84E-07,1.15E-03,1.91E-03,1.00E+00,3.00E+00,9.98E+01,1878,10,3,4,0,1,1,4.00E+00,1,2.48E-02,0.00E+00,0,0.00E+00
1713516238,,0.00E+00,1.70E+02,1.08E-03,3.98E-07,-5.81E-06,6.92E-08,1.08E-03,3.98E-07,-3.07E-01,3.57E-03,1.00E+00,3.00E+00,9.97E+02,188,10,3,4,0,0,1,4.00E+00,1,9.99E-03,0.00E+00,0,0.00E+00
1713516786,,0.00E+00,1.75E+02,1.04E-03,5.49E-07,-3.44E-07,3.05E-08,1.04E-03,5.49E-07,-1.90E-02,1.69E-03,1.00E+00,3.00E+00,1.00E+00,732,10,3,2,0,3,1,4.00E+00,1,2.09E-02,0.00E+00,0,0.00E+00
1713516971,,0.00E+00,1.75E+02,1.04E-03,3.45E-07,-1.13E-06,2.73E-08,1.04E-03,3.45E-07,-6.26E-02,1.50E-03,1.00E+00,3.00E+00,1.00E+01,1172,10,3,3,0,2,1,4.00E+00,1,1.05E-02,0.00E+00,0,0.00E+00
1713517161,,0.00E+00,1.75E+02,1.04E-03,4.88E-07,-2.83E-08,5.75E-08,1.04E-03,4.88E-07,-1.56E-03,3.18E-03,1.00E+00,3.00E+00,9.98E+01,1878,10,3,4,0,1,1,4.00E+00,1,1.05E-02,0.00E+00,0,0.00E+00
1713517350,,0.00E+00,1.75E+02,1.05E-03,4.00E-07,-5.51E-06,1.30E-07,1.05E-03,4.00E-07,-3.02E-01,7.06E-03,1.00E+00,3.00E+00,9.97E+02,188,10,3,4,0,0,1,4.00E+00,1,1.57E-02,0.00E+00,0,0.00E+00
1713517894,,0.00E+00,1.80E+02,1.00E-03,4.92E-07,-2.77E-07,2.49E-08,1.00E-03,4.92E-07,-1.59E-02,1.44E-03,1.00E+00,3.00E+00,1.00E+00,732,10,3,2,0,3,1,4.00E+00,1,5.49E-03,0.00E+00,0,0.00E+00
1713518075,,0.00E+00,1.80E+02,1.00E-03,3.42E-07,-1.05E-06,1.13E-08,1.00E-03,3.42E-07,-6.03E-02,6.53E-04,1.00E+00,3.00E+00,1.00E+01,1172,10,3,3,0,2,1,4.00E+00,1,1.65E-02,0.00E+00,0,0.00E+00
1713518255,,0.00E+00,1.80E+02,1.00E-03,4.68E-07,-6.50E-08,3.12E-08,1.00E-03,4.68E-07,-3.72E-03,1.79E-03,1.00E+00,3.00E+00,9.98E+01,1878,10,3,4,0,1,1,4.00E+00,1,2.20E-02,0.00E+00,0,0.00E+00
1713518420,,0.00E+00,1.80E+02,1.01E-03,4.09E-07,-5.40E-06,1.04E-07,1.01E-03,4.08E-07,-3.06E-01,6.04E-03,1.00E+00,3.00E+00,9.97E+02,188,10,3,4,0,0,1,4.00E+00,1,1.65E-02,0.00E+00,0,0.00E+00
1713518944,,0.00E+00,1.85E+02,9.67E-04,5.71E-07,-2.84E-07,2.36E-08,9.67E-04,5.71E-07,-1.68E-02,1.39E-03,1.00E+00,3.00E+00,1.00E+00,732,10,3,2,0,3,1,4.00E+00,1,2.32E-02,0.00E+00,0,0.00E+00
1713519122,,0.00E+00,1.85E+02,9.67E-04,3.87E-07,-9.58E-07,8.97E-09,9.67E-04,3.87E-07,-5.67E-02,5.50E-04,1.00E+00,3.00E+00,1.00E+01,1172,10,3,3,0,2,1,4.00E+00,1,1.74E-02,0.00E+00,0,0.00E+00
1713519293,,0.00E+00,1.85E+02,9.68E-04,4.79E-07,-1.07E-07,2.75E-08,9.68E-04,4.79E-07,-6.32E-03,1.62E-03,1.00E+00,3.00E+00,9.98E+01,1878,10,3,4,0,1,1,4.00E+00,1,2.90E-02,0.00E+00,0,0.00E+00
1713519462,,0.00E+00,1.85E+02,9.77E-04,5.74E-07,-5.23E-06,6.25E-08,9.77E-04,5.73E-07,-3.07E-01,3.74E-03,1.00E+00,3.00E+00,9.97E+02,188,10,3,4,0,0,1,4.00E+00,1,1.16E-02,0.00E+00,0,0.00E+00
1713520008,,0.00E+00,1.90E+02,9.35E-04,2.34E-07,-2.19E-07,3.62E-08,9.35E-04,2.34E-07,-1.34E-02,2.23E-03,1.00E+00,3.00E+00,1.00E+00,732,10,3,2,0,3,1,4.00E+00,1,1.22E-02,0.00E+00,0,0.00E+00
1713520192,,0.00E+00,1.90E+02,9.35E-04,4.15E-07,-8.69E-07,1.36E-08,9.35E-04,4.15E-07,-5.33E-02,8.10E-04,1.00E+00,3.00E+00,1.00E+01,1172,10,3,3,0,2,1,4.00E+00,1,2.44E-02,0.00E+00,0,0.00E+00
1713520364,,0.00E+00,1.90E+02,9.35E-04,3.16E-07,-1.50E-07,4.23E-09,9.35E-04,3.16E-07,-9.22E-03,2.66E-04,1.00E+00,3.00E+00,9.98E+01,1878,10,3,4,0,1,1,4.00E+00,1,1.83E-02,0.00E+00,0,0.00E+00
1713520578,,0.00E+00,1.90E+02,9.44E-04,3.69E-07,-5.10E-06,4.60E-08,9.44E-04,3.69E-07,-3.10E-01,2.69E-03,1.00E+00,3.00E+00,9.97E+02,188,10,3,4,0,0,1,4.00E+00,1,2.44E-02,0.00E+00,0,0.00E+00
1713521112,,0.00E+00,1.95E+02,9.05E-04,3.85E-07,-1.93E-07,5.65E-08,9.05E-04,3.85E-07,-1.22E-02,3.58E-03,1.00E+00,3.00E+00,1.00E+00,732,10,3,2,0,3,1,4.00E+00,1,2.56E-02,0.00E+00,0,0.00E+00
1713521292,,0.00E+00,1.95E+02,9.05E-04,3.35E-07,-7.65E-07,8.70E-09,9.05E-04,3.35E-07,-4.84E-02,5.36E-04,1.00E+00,3.00E+00,1.00E+01,1172,10,3,3,0,2,1,4.00E+00,1,1.92E-02,0.00E+00,0,0.00E+00
1713521468,,0.00E+00,1.95E+02,9.05E-04,3.45E-07,-2.14E-07,2.02E-08,9.05E-04,3.45E-07,-1.35E-02,1.29E-03,1.00E+00,3.00E+00,9.98E+01,1878,10,3,4,0,1,1,4.00E+00,1,1.28E-02,0.00E+00,0,0.00E+00
1713521633,,0.00E+00,1.95E+02,9.13E-04,4.80E-07,-4.80E-06,5.88E-08,9.13E-04,4.80E-07,-3.01E-01,3.82E-03,1.00E+00,3.00E+00,9.97E+02,188,10,3,4,0,0,1,4.00E+00,1,1.28E-02,0.00E+00,0,0.00E+00
1713522169,,0.00E+00,2.00E+02,8.75E-04,3.97E-07,-1.91E-07,1.86E-08,8.75E-04,3.97E-07,-1.25E-02,1.22E-03,1.00E+00,3.00E+00,1.00E+00,732,10,3,2,0,3,1,4.00E+00,1,2.01E-02,0.00E+00,0,0.00E+00
1713522350,,0.00E+00,2.00E+02,8.75E-04,3.77E-07,-7.25E-07,5.91E-09,8.75E-04,3.77E-07,-4.75E-02,4.03E-04,1.00E+00,3.00E+00,1.00E+01,1172,10,3,3,0,2,1,4.00E+00,1,6.70E-03,0.00E+00,0,0.00E+00
1713522521,,0.00E+00,2.00E+02,8.75E-04,3.85E-07,-1.98E-07,1.74E-08,8.75E-04,3.85E-07,-1.30E-02,1.13E-03,1.00E+00,3.00E+00,9.98E+01,1878,10,3,4,0,1,1,4.00E+00,1,2.02E-02,0.00E+00,0,0.00E+00
1713522708,,0.00E+00,2.00E+02,8.83E-04,4.40E-07,-4.68E-06,6.70E-08,8.83E-04,4.40E-07,-3.03E-01,4.31E-03,1.00E+00,3.00E+00,9.97E+02,188,10,3,4,0,0,1,4.00E+00,1,1.34E-02,0.00E+00,0,0.00E+00
1713523237,,0.00E+00,2.05E+02,8.47E-04,3.75E-07,-1.71E-07,2.03E-08,8.47E-04,3.75E-07,-1.16E-02,1.37E-03,1.00E+00,3.00E+00,1.00E+00,732,10,3,2,0,3,1,4.00E+00,1,2.11E-02,0.00E+00,0,0.00E+00
1713523405,,0.00E+00,2.05E+02,8.47E-04,4.69E-07,-6.81E-07,2.57E-08,8.47E-04,4.69E-07,-4.61E-02,1.72E-03,1.00E+00,3.00E+00,1.00E+01,1172,10,3,3,0,2,1,4.00E+00,1,3.52E-02,0.00E+00,0,0.00E+00
1713523578,,0.00E+00,2.05E+02,8.47E-04,3.80E-07,-2.33E-07,3.58E-08,8.47E-04,3.80E-07,-1.57E-02,2.41E-03,1.00E+00,3.00E+00,9.98E+01,1878,10,3,4,0,1,1,4.00E+00,1,2.81E-02,0.00E+00,0,0.00E+00
1713523749,,0.00E+00,2.05E+02,8.54E-04,3.89E-07,-4.49E-06,1.06E-07,8.54E-04,3.89E-07,-3.01E-01,7.22E-03,1.00E+00,3.00E+00,9.97E+02,188,10,3,4,0,0,1,4.00E+00,1,1.41E-02,0.00E+00,0,0.00E+00
1713524302,,0.00E+00,2.10E+02,8.20E-04,3.22E-07,-1.60E-07,2.86E-08,8.20E-04,3.22E-07,-1.12E-02,2.00E-03,1.00E+00,3.00E+00,1.00E+00,732,10,3,2,0,3,1,4.00E+00,1,2.94E-02,0.00E+00,0,0.00E+00
1713524486,,0.00E+00,2.10E+02,8.20E-04,3.65E-07,-6.34E-07,1.94E-08,8.20E-04,3.65E-07,-4.43E-02,1.33E-03,1.00E+00,3.00E+00,1.00E+01,1172,10,3,3,0,2,1,4.00E+00,1,2.21E-02,0.00E+00,0,0.00E+00
1713524666,,0.00E+00,2.10E+02,8.20E-04,3.70E-07,-2.13E-07,7.49E-09,8.20E-04,3.70E-07,-1.49E-02,5.25E-04,1.00E+00,3.00E+00,9.98E+01,1878,10,3,4,0,1,1,4.00E+00,1,2.21E-02,0.00E+00,0,0.00E+00
1713524866,,0.00E+00,2.10E+02,8.27E-04,5.62E-07,-4.38E-06,1.48E-07,8.27E-04,5.62E-07,-3.03E-01,1.02E-02,1.00E+00,3.00E+00,9.97E+02,188,10,3,4,0,0,1,4.00E+00,1,2.20E-02,0.00E+00,0,0.00E+00
1713525388,,0.00E+00,2.15E+02,7.94E-04,4.06E-07,-1.60E-07,2.30E-08,7.94E-04,4.06E-07,-1.15E-02,1.66E-03,1.00E+00,3.00E+00,1.00E+00,732,10,3,2,0,3,1,4.00E+00,1,2.31E-02,0.00E+00,0,0.00E+00
1713525591,,0.00E+00,2.15E+02,7.94E-04,3.87E-07,-5.98E-07,1.38E-08,7.94E-04,3.87E-07,-4.32E-02,9.79E-04,1.00E+00,3.00E+00,1.00E+01,1172,10,3,3,0,2,1,4.00E+00,1,2.31E-02,0.00E+00,0,0.00E+00
1713525772,,0.00E+00,2.15E+02,7.94E-04,3.97E-07,-2.34E-07,2.60E-08,7.94E-04,3.97E-07,-1.69E-02,1.86E-03,1.00E+00,3.00E+00,9.98E+01,1878,10,3,4,0,1,1,4.00E+00,1,2.31E-02,0.00E+00,0,0.00E+00
1713525945,,0.00E+00,2.15E+02,8.00E-04,3.44E-07,-4.19E-06,6.14E-08,8.00E-04,3.44E-07,-3.00E-01,4.36E-03,1.00E+00,3.00E+00,9.97E+02,188,10,3,4,0,0,1,4.00E+00,1,1.54E-02,0.00E+00,0,0.00E+00
1713526464,,0.00E+00,2.20E+02,7.69E-04,4.67E-07,-1.90E-07,4.95E-08,7.69E-04,4.67E-07,-1.41E-02,3.68E-03,1.00E+00,3.00E+00,1.00E+00,732,10,3,2,0,3,1,4.00E+00,1,1.60E-02,0.00E+00,0,0.00E+00
1713526659,,0.00E+00,2.20E+02,7.68E-04,3.70E-07,-5.91E-07,7.56E-09,7.68E-04,3.70E-07,-4.41E-02,5.87E-04,1.00E+00,3.00E+00,1.00E+01,1172,10,3,3,0,2,1,4.00E+00,1,3.22E-02,0.00E+00,0,0.00E+00
1713526833,,0.00E+00,2.20E+02,7.68E-04,3.66E-07,-1.76E-07,1.58E-08,7.68E-04,3.66E-07,-1.32E-02,1.18E-03,1.00E+00,3.00E+00,9.98E+01,1878,10,3,4,0,1,1,4.00E+00,1,1.60E-02,0.00E+00,0,0.00E+00
1713527007,,0.00E+00,2.20E+02,7.75E-04,5.30E-07,-4.12E-06,9.72E-08,7.75E-04,5.30E-07,-3.05E-01,7.39E-03,1.00E+00,3.00E+00,9.97E+02,188,10,3,4,0,0,1,4.00E+00,1,4.83E-02,0.00E+00,0,0.00E+00
1713527536,,0.00E+00,2.25E+02,7.45E-04,4.38E-07,-1.78E-07,6.09E-09,7.45E-04,4.38E-07,-1.37E-02,4.77E-04,1.00E+00,3.00E+00,1.00E+00,732,10,3,2,0,3,1,4.00E+00,1,1.69E-02,0.00E+00,0,0.00E+00
1713527741,,0.00E+00,2.25E+02,7.45E-04,4.70E-07,-6.00E-07,1.18E-08,7.45E-04,4.70E-07,-4.61E-02,8.83E-04,1.00E+00,3.00E+00,1.00E+01,1172,10,3,3,0,2,1,4.00E+00,1,2.52E-02,0.00E+00,0,0.00E+00
1713527919,,0.00E+00,2.25E+02,7.45E-04,3.77E-07,-1.69E-07,4.55E-08,7.45E-04,3.77E-07,-1.30E-02,3.49E-03,1.00E+00,3.00E+00,9.98E+01,1878,10,3,4,0,1,1,4.00E+00,1,3.37E-02,0.00E+00,0,0.00E+00
1713528067,,0.00E+00,2.25E+02,7.51E-04,4.12E-07,-3.89E-06,8.14E-08,7.51E-04,4.12E-07,-2.97E-01,6.31E-03,1.00E+00,3.00E+00,9.97E+02,188,10,3,4,0,0,1,4.00E+00,1,1.68E-02,0.00E+00,0,0.00E+00
1713528588,,0.00E+00,2.30E+02,7.22E-04,3.31E-07,-2.03E-07,1.21E-08,7.22E-04,3.31E-07,-1.61E-02,9.59E-04,1.00E+00,3.00E+00,1.00E+00,732,10,3,2,0,3,1,4.00E+00,1,8.79E-03,0.00E+00,0,0.00E+00
1713528794,,0.00E+00,2.30E+02,7.21E-04,4.89E-07,-5.77E-07,9.43E-09,7.21E-04,4.89E-07,-4.58E-02,7.27E-04,1.00E+00,3.00E+00,1.00E+01,1172,10,3,3,0,2,1,4.00E+00,1,4.38E-02,0.00E+00,0,0.00E+00
1713528955,,0.00E+00,2.30E+02,7.22E-04,3.55E-07,-1.24E-07,4.18E-09,7.22E-04,3.55E-07,-9.86E-03,3.22E-04,1.00E+00,3.00E+00,9.98E+01,1878,10,3,4,0,1,1,4.00E+00,1,1.75E-02,0.00E+00,0,0.00E+00
1713529127,,0.00E+00,2.30E+02,7.28E-04,4.46E-07,-3.26E-06,8.64E-08,7.28E-04,4.45E-07,-2.57E-01,6.90E-03,1.00E+00,3.00E+00,9.97E+02,188,10,3,4,0,0,1,4.00E+00,1,2.63E-02,0.00E+00,0,0.00E+00
1713529654,,0.00E+00,2.35E+02,7.00E-04,3.44E-07,-1.88E-07,2.59E-08,7.00E-04,3.44E-07,-1.54E-02,2.12E-03,1.00E+00,3.00E+00,1.00E+00,732,10,3,2,0,3,1,4.00E+00,1,2.74E-02,0.00E+00,0,0.00E+00
1713529838,,0.00E+00,2.35E+02,6.99E-04,3.39E-07,-5.62E-07,1.14E-08,6.99E-04,3.39E-07,-4.61E-02,9.18E-04,1.00E+00,3.00E+00,1.00E+01,1172,10,3,3,0,2,1,4.00E+00,1,2.74E-02,0.00E+00,0,0.00E+00
1713530011,,0.00E+00,2.35E+02,7.00E-04,3.33E-07,-1.08E-07,2.43E-08,7.00E-04,3.33E-07,-8.88E-03,1.99E-03,1.00E+00,3.00E+00,9.98E+01,1878,10,3,4,0,1,1,4.00E+00,1,2.74E-02,0.00E+00,0,0.00E+00
1713530186,,0.00E+00,2.35E+02,7.06E-04,2.75E-07,-3.06E-06,4.44E-08,7.06E-04,2.75E-07,-2.49E-01,3.53E-03,1.00E+00,3.00E+00,9.97E+02,188,10,3,4,0,0,1,4.00E+00,1,2.74E-02,0.00E+00,0,0.00E+00
1713530708,,0.00E+00,2.40E+02,6.78E-04,3.80E-07,-1.84E-07,3.17E-08,6.78E-04,3.80E-07,-1.55E-02,2.69E-03,1.00E+00,3.00E+00,1.00E+00,732,10,3,2,0,3,1,4.00E+00,1,1.91E-02,0.00E+00,0,0.00E+00
1713530908,,0.00E+00,2.40E+02,6.78E-04,3.03E-07,-5.58E-07,7.47E-09,6.78E-04,3.03E-07,-4.72E-02,6.39E-04,1.00E+00,3.00E+00,1.00E+01,1172,10,3,3,0,2,1,4.00E+00,1,9.51E-03,0.00E+00,0,0.00E+00
1713531069,,0.00E+00,2.40E+02,6.78E-04,4.20E-07,-7.51E-08,5.64E-10,6.78E-04,4.20E-07,-6.35E-03,4.83E-05,1.00E+00,3.00E+00,9.98E+01,1878,10,3,4,0,1,1,4.00E+00,1,1.90E-02,0.00E+00,0,0.00E+00
1713531229,,0.00E+00,2.40E+02,6.84E-04,3.01E-07,-3.00E-06,1.17E-07,6.84E-04,3.02E-07,-2.52E-01,9.72E-03,1.00E+00,3.00E+00,9.97E+02,188,10,3,4,0,0,1,4.00E+00,1,1.90E-02,0.00E+00,0,0.00E+00
1713531765,,0.00E+00,2.45E+02,6.57E-04,3.74E-07,-2.10E-07,2.41E-08,6.57E-04,3.74E-07,-1.83E-02,2.09E-03,1.00E+00,3.00E+00,1.00E+00,732,10,3,2,0,3,1,4.00E+00,1,2.97E-02,0.00E+00,0,0.00E+00
1713531961,,0.00E+00,2.45E+02,6.57E-04,3.09E-07,-5.41E-07,9.54E-09,6.57E-04,3.09E-07,-4.72E-02,8.19E-04,1.00E+00,3.00E+00,1.00E+01,1172,10,3,3,0,2,1,4.00E+00,1,1.98E-02,0.00E+00,0,0.00E+00
1713532133,,0.00E+00,2.45E+02,6.57E-04,3.54E-07,-6.36E-08,3.26E-08,6.57E-04,3.54E-07,-5.55E-03,2.85E-03,1.00E+00,3.00E+00,9.98E+01,1878,10,3,4,0,1,1,4.00E+00,1,2.97E-02,0.00E+00,0,0.00E+00
1713532297,,0.00E+00,2.45E+02,6.63E-04,3.45E-07,-2.86E-06,1.46E-07,6.63E-04,3.44E-07,-2.47E-01,1.27E-02,1.00E+00,3.00E+00,9.97E+02,188,10,3,4,0,0,1,4.00E+00,1,3.97E-02,0.00E+00,0,0.00E+00
1713532824,,0.00E+00,2.50E+02,6.37E-04,3.41E-07,-2.11E-07,2.35E-08,6.37E-04,3.41E-07,-1.90E-02,2.12E-03,1.00E+00,3.00E+00,1.00E+00,732,10,3,2,0,3,1,4.00E+00,1,5.15E-02,0.00E+00,0,0.00E+00
1713533023,,0.00E+00,2.50E+02,6.37E-04,4.12E-07,-5.41E-07,1.53E-08,6.37E-04,4.12E-07,-4.87E-02,1.39E-03,1.00E+00,3.00E+00,1.00E+01,1172,10,3,3,0,2,1,4.00E+00,1,1.03E-02,0.00E+00,0,0.00E+00
1713533199,,0.00E+00,2.50E+02,6.37E-04,3.54E-07,-4.81E-08,3.06E-08,6.37E-04,3.54E-07,-4.33E-03,2.76E-03,1.00E+00,3.00E+00,9.98E+01,1878,10,3,4,0,1,1,4.00E+00,1,3.09E-02,0.00E+00,0,0.00E+00
1713533373,,0.00E+00,2.50E+02,6.43E-04,3.48E-07,-2.77E-06,7.53E-08,6.43E-04,3.48E-07,-2.47E-01,6.79E-03,1.00E+00,3.00E+00,9.97E+02,188,10,3,4,0,0,1,4.00E+00,1,1.03E-02,0.00E+00,0,0.00E+00
1713533910,,0.00E+00,2.55E+02,6.17E-04,3.13E-07,-1.83E-07,1.70E-08,6.17E-04,3.13E-07,-1.70E-02,1.57E-03,1.00E+00,3.00E+00,1.00E+00,732,10,3,2,0,3,1,4.00E+00,1,3.21E-02,0.00E+00,0,0.00E+00
1713534101,,0.00E+00,2.55E+02,6.17E-04,2.96E-07,-5.33E-07,2.31E-08,6.17E-04,2.96E-07,-4.95E-02,2.16E-03,1.00E+00,3.00E+00,1.00E+01,1172,10,3,3,0,2,1,4.00E+00,1,3.21E-02,0.00E+00,0,0.00E+00
1713534290,,0.00E+00,2.55E+02,6.17E-04,3.19E-07,-3.96E-08,4.12E-09,6.17E-04,3.19E-07,-3.69E-03,3.88E-04,1.00E+00,3.00E+00,9.98E+01,1878,10,3,4,0,1,1,4.00E+00,1,3.21E-02,0.00E+00,0,0.00E+00
1713534473,,0.00E+00,2.55E+02,6.23E-04,2.43E-07,-2.76E-06,7.44E-08,6.23E-04,2.43E-07,-2.54E-01,6.87E-03,1.00E+00,3.00E+00,9.97E+02,188,10,3,4,0,0,1,4.00E+00,1,1.07E-02,0.00E+00,0,0.00E+00
1713534998,,0.00E+00,2.60E+02,5.98E-04,2.77E-07,-2.09E-07,1.54E-08,5.98E-04,2.77E-07,-2.01E-02,1.49E-03,1.00E+00,3.00E+00,1.00E+00,732,10,3,2,0,3,1,4.00E+00,1,1.10E-02,0.00E+00,0,0.00E+00
1713535199,,0.00E+00,2.60E+02,5.98E-04,3.16E-07,-5.25E-07,5.09E-09,5.98E-04,3.16E-07,-5.03E-02,4.91E-04,1.00E+00,3.00E+00,1.00E+01,1172,10,3,3,0,2,1,4.00E+00,1,3.33E-02,0.00E+00,0,0.00E+00
1713535362,,0.00E+00,2.60E+02,5.98E-04,3.37E-07,-3.81E-08,1.48E-08,5.98E-04,3.37E-07,-3.66E-03,1.42E-03,1.00E+00,3.00E+00,9.98E+01,1878,10,3,4,0,1,1,4.00E+00,1,3.33E-02,0.00E+00,0,0.00E+00
1713535542,,0.00E+00,2.60E+02,6.04E-04,2.40E-07,-2.59E-06,8.15E-08,6.04E-04,2.40E-07,-2.46E-01,7.66E-03,1.00E+00,3.00E+00,9.97E+02,188,10,3,4,0,0,1,4.00E+00,1,3.33E-02,0.00E+00,0,0.00E+00
1713536048,,0.00E+00,2.65E+02,5.80E-04,2.41E-07,-2.07E-07,1.53E-08,5.80E-04,2.41E-07,-2.05E-02,1.52E-03,1.00E+00,3.00E+00,1.00E+00,732,10,3,2,0,3,1,4.00E+00,1,1.15E-02,0.00E+00,0,0.00E+00
1713536228,,0.00E+00,2.65E+02,5.80E-04,2.81E-07,-4.87E-07,9.13E-09,5.80E-04,2.81E-07,-4.82E-02,8.80E-04,1.00E+00,3.00E+00,1.00E+01,1172,10,3,3,0,2,1,4.00E+00,1,3.47E-02,0.00E+00,0,0.00E+00
1713536397,,0.00E+00,2.65E+02,5.80E-04,2.32E-07,-5.94E-08,4.50E-08,5.80E-04,2.32E-07,-5.86E-03,4.45E-03,1.00E+00,3.00E+00,9.98E+01,1878,10,3,4,0,1,1,4.00E+00,1,2.31E-02,0.00E+00,0,0.00E+00
1713536568,,0.00E+00,2.65E+02,5.85E-04,3.95E-07,-2.52E-06,3.95E-08,5.85E-04,3.95E-07,-2.46E-01,3.84E-03,1.00E+00,3.00E+00,9.97E+02,188,10,3,4,0,0,1,4.00E+00,1,2.31E-02,0.00E+00,0,0.00E+00
1713537096,,0.00E+00,2.70E+02,5.62E-04,2.36E-07,-1.77E-07,3.28E-08,5.62E-04,2.36E-07,-1.80E-02,3.33E-03,1.00E+00,3.00E+00,1.00E+00,732,10,3,2,0,3,1,4.00E+00,1,6.01E-02,0.00E+00,0,0.00E+00
1713537285,,0.00E+00,2.70E+02,5.62E-04,2.22E-07,-4.76E-07,2.92E-09,5.62E-04,2.22E-07,-4.86E-02,2.89E-04,1.00E+00,3.00E+00,1.00E+01,1172,10,3,3,0,2,1,4.00E+00,1,2.41E-02,0.00E+00,0,0.00E+00
1713537454,,0.00E+00,2.70E+02,5.62E-04,2.23E-07,-1.03E-08,3.43E-08,5.62E-04,2.23E-07,-1.07E-03,3.50E-03,1.00E+00,3.00E+00,9.98E+01,1878,10,3,4,0,1,1,4.00E+00,1,3.61E-02,0.00E+00,0,0.00E+00
1713537610,,0.00E+00,2.70E+02,5.67E-04,2.36E-07,-2.49E-06,7.88E-08,5.67E-04,2.36E-07,-2.52E-01,7.87E-03,1.00E+00,3.00E+00,9.97E+02,188,10,3,4,0,0,1,4.00E+00,1,1.21E-02,0.00E+00,0,0.00E+00
1713538143,,0.00E+00,2.75E+02,5.45E-04,2.57E-07,-1.82E-07,1.77E-08,5.45E-04,2.57E-07,-1.91E-02,1.86E-03,1.00E+00,3.00E+00,1.00E+00,732,10,3,2,0,3,1,4.00E+00,1,3.75E-02,0.00E+00,0,0.00E+00
1713538331,,0.00E+00,2.75E+02,5.45E-04,2.14E-07,-4.64E-07,2.31E-09,5.45E-04,2.14E-07,-4.88E-02,2.29E-04,1.00E+00,3.00E+00,1.00E+01,1172,10,3,3,0,2,1,4.00E+00,1,2.50E-02,0.00E+00,0,0.00E+00
1713538507,,0.00E+00,2.75E+02,5.45E-04,2.30E-07,-2.58E-08,1.64E-08,5.45E-04,2.30E-07,-2.72E-03,1.72E-03,1.00E+00,3.00E+00,9.98E+01,1878,10,3,4,0,1,1,4.00E+00,1,1.25E-02,0.00E+00,0,0.00E+00
1713538659,,0.00E+00,2.75E+02,5.50E-04,1.12E-07,-2.35E-06,1.10E-07,5.50E-04,1.12E-07,-2.45E-01,1.15E-02,1.00E+00,3.00E+00,9.97E+02,188,10,3,4,0,0,1,4.00E+00,1,1.25E-02,0.00E+00,0,0.00E+00
1713539182,,0.00E+00,2.80E+02,5.29E-04,2.84E-07,-1.83E-07,2.35E-08,5.29E-04,2.84E-07,-1.99E-02,2.53E-03,1.00E+00,3.00E+00,1.00E+00,732,10,3,2,0,3,1,4.00E+00,1,2.60E-02,0.00E+00,0,0.00E+00
1713539373,,0.00E+00,2.80E+02,5.29E-04,2.50E-07,-4.59E-07,1.26E-08,5.29E-04,2.50E-07,-4.97E-02,1.37E-03,1.00E+00,3.00E+00,1.00E+01,1172,10,3,3,0,2,1,4.00E+00,1,1.30E-02,0.00E+00,0,0.00E+00
1713539541,,0.00E+00,2.80E+02,5.29E-04,2.06E-07,-2.80E-08,2.35E-08,5.29E-04,2.06E-07,-3.05E-03,2.54E-03,1.00E+00,3.00E+00,9.98E+01,1878,10,3,4,0,1,1,4.00E+00,1,3.89E-02,0.00E+00,0,0.00E+00
1713539704,,0.00E+00,2.80E+02,5.33E-04,2.62E-07,-2.28E-06,5.04E-08,5.33E-04,2.62E-07,-2.44E-01,5.34E-03,1.00E+00,3.00E+00,9.97E+02,188,10,3,4,0,0,1,4.00E+00,1,1.30E-02,0.00E+00,0,0.00E+00
1713540231,,0.00E+00,2.85E+02,5.13E-04,2.14E-07,-1.95E-07,1.50E-08,5.13E-04,2.14E-07,-2.17E-02,1.68E-03,1.00E+00,3.00E+00,1.00E+00,732,10,3,2,0,3,1,4.00E+00,1,2.69E-02,0.00E+00,0,0.00E+00
1713540425,,0.00E+00,2.85E+02,5.13E-04,2.02E-07,-4.54E-07,9.65E-09,5.13E-04,2.02E-07,-5.07E-02,1.07E-03,1.00E+00,3.00E+00,1.00E+01,1172,10,3,3,0,2,1,4.00E+00,1,2.69E-02,0.00E+00,0,0.00E+00
1713540607,,0.00E+00,2.85E+02,5.13E-04,2.08E-07,-3.22E-08,3.75E-09,5.13E-04,2.08E-07,-3.60E-03,4.13E-04,1.00E+00,3.00E+00,9.98E+01,1878,10,3,4,0,1,1,4.00E+00,1,2.69E-02,0.00E+00,0,0.00E+00
1713540817,,0.00E+00,2.85E+02,5.17E-04,1.41E-07,-2.23E-06,1.55E-07,5.17E-04,1.41E-07,-2.47E-01,1.71E-02,1.00E+00,3.00E+00,9.97E+02,188,10,3,4,0,0,1,4.00E+00,1,1.34E-02,0.00E+00,0,0.00E+00
1713541357,,0.00E+00,2.90E+02,4.98E-04,1.99E-07,-1.81E-07,2.77E-08,4.98E-04,1.99E-07,-2.08E-02,3.18E-03,1.00E+00,3.00E+00,1.00E+00,732,10,3,2,0,3,1,4.00E+00,1,2.79E-02,0.00E+00,0,0.00E+00
1713541557,,0.00E+00,2.90E+02,4.98E-04,2.08E-07,-4.23E-07,1.03E-08,4.98E-04,2.08E-07,-4.86E-02,1.17E-03,1.00E+00,3.00E+00,1.00E+01,1172,10,3,3,0,2,1,4.00E+00,1,1.39E-02,0.00E+00,0,0.00E+00
1713541731,,0.00E+00,2.90E+02,4.98E-04,2.00E-07,-1.55E-08,1.61E-08,4.98E-04,2.00E-07,-1.77E-03,1.86E-03,1.00E+00,3.00E+00,9.98E+01,1878,10,3,4,0,1,1,4.00E+00,1,4.18E-02,0.00E+00,0,0.00E+00
1713541891,,0.00E+00,2.90E+02,5.02E-04,1.67E-07,-2.21E-06,1.24E-07,5.02E-04,1.67E-07,-2.52E-01,1.41E-02,1.00E+00,3.00E+00,9.97E+02,188,10,3,4,0,0,1,4.00E+00,1,1.39E-02,0.00E+00,0,0.00E+00
1713542433,,0.00E+00,2.95E+02,4.83E-04,2.28E-07,-1.51E-07,1.01E-08,4.83E-04,2.28E-07,-1.79E-02,1.21E-03,1.00E+00,3.00E+00,1.00E+00,732,10,3,2,0,3,1,4.00E+00,1,2.89E-02,0.00E+00,0,0.00E+00
1713542648,,0.00E+00,2.95E+02,4.83E-04,1.68E-07,-3.90E-07,7.37E-09,4.83E-04,1.68E-07,-4.63E-02,8.77E-04,1.00E+00,3.00E+00,1.00E+01,1172,10,3,3,0,2,1,4.00E+00,1,2.89E-02,0.00E+00,0,0.00E+00
1713542812,,0.00E+00,2.95E+02,4.83E-04,1.90E-07,-2.19E-08,1.62E-08,4.83E-04,1.90E-07,-2.59E-03,1.92E-03,1.00E+00,3.00E+00,9.98E+01,1878,10,3,4,0,1,1,4.00E+00,1,1.45E-02,0.00E+00,0,0.00E+00
1713542998,,0.00E+00,2.95E+02,4.88E-04,2.83E-07,-2.13E-06,1.19E-07,4.88E-04,2.84E-07,-2.51E-01,1.39E-02,1.00E+00,3.00E+00,9.97E+02,188,10,3,4,0,0,1,4.00E+00,1,1.45E-02,0.00E+00,0,0.00E+00
1713543523,,0.00E+00,3.00E+02,4.69E-04,1.75E-07,-1.42E-07,2.67E-08,4.69E-04,1.75E-07,-1.73E-02,3.25E-03,1.00E+00,3.00E+00,1.00E+00,732,10,3,2,0,3,1,4.00E+00,1,4.48E-02,0.00E+00,0,0.00E+00
1713543698,,0.00E+00,3.00E+02,4.69E-04,1.36E-07,-3.77E-07,2.48E-08,4.69E-04,1.36E-07,-4.61E-02,3.03E-03,1.00E+00,3.00E+00,1.00E+01,1172,10,3,3,0,2,1,4.00E+00,1,1.49E-02,0.00E+00,0,0.00E+00
1713543858,,0.00E+00,3.00E+02,4.69E-04,1.49E-07,-2.83E-08,1.97E-08,4.69E-04,1.49E-07,-3.45E-03,2.40E-03,1.00E+00,3.00E+00,9.98E+01,1878,10,3,4,0,1,1,4.00E+00,1,1.49E-02,0.00E+00,0,0.00E+00
1713544038,,0.00E+00,3.00E+02,4.73E-04,2.23E-07,-2.06E-06,1.30E-07,4.73E-04,2.23E-07,-2.50E-01,1.57E-02,1.00E+00,3.00E+00,9.97E+02,188,10,3,4,0,0,1,4.00E+00,1,2.99E-02,0.00E+00,0,0.00E+00